Workbook

Sheet Cockpit
A1: IT | B1: IT Process Portfolio – Cockpit
B2: Datenstand Draft April 2026 · Quelle: Process_Portfolio_Timeline.xlsx · Mappe erzeugt am 01.09.2026
B3: Auswahlfelder ändern – Kennzahlen, Diagramme und Liste rechnen sofort neu.
B5: PROZESSGRUPPE | C5: INITIATIVE | D5: L1-PROZESS | E5: EBENE | F5: STATUS | G5: PROCESS MANAGER | H5: STICHTAG
B6: (Alle) | C6: (Alle) | D6: (Alle) | E6: (Alle) | F6: (Alle) | G6: (Alle) | H6: 46266
B8: PROZESSE IM FILTER | C8: Ø FORTSCHRITT | D8: VERZÖGERT | E8: ÜBERFÄLLIG | F8: ELABORATION FERTIG | G8: IN IMPLEMENTIERUNG | H8: TERMINE IN 90 TAGEN
B9: =SUM(Prozesse!$S$2:$S$125) -> 124 | C9: =IFERROR(SUMPRODUCT(Prozesse!$S$2:$S$125,Prozesse!$I$2:$I$125)/SUM(Prozesse!$S$2:$S$125),0) -> 0.40395161 | D9: =SUMPRODUCT(Prozesse!$S$2:$S$125,--(Prozesse!$H$2:$H$125="Verzögert")) -> 29 | E9: =SUMPRODUCT(Prozesse!$S$2:$S$125,Prozesse!$Q$2:$Q$125) -> 52 | F9: =SUMPRODUCT(Prozesse!$S$2:$S$125,--(Prozesse!$M$2:$M$125="Abgeschlossen")) -> 30 | G9: =SUMPRODUCT(Prozesse!$S$2:$S$125,Prozesse!$R$2:$R$125) -> 20 | H9: =SUMPRODUCT(Phasen!$I$2:$I$497,--(Phasen!$G$2:$G$497>=$H$6),--(Phasen!$G$2:$G$497<=$H$6+90)) -> 8
B58: PROZESSE IM FILTER – VERZÖGERTE ZUERST, ERSTE 15
B59: Prozess | C59: Gruppe | D59: Status | E59: % fertig | F59: Ende | G59: Process Manager
B60: =IFERROR(INDEX(Prozesse!$B$2:$B$125,MATCH(1,Prozesse!$T$2:$T$125,0)),"") -> Analyse architecture impact | C60: =IFERROR(INDEX(Prozesse!$D$2:$D$125,MATCH(1,Prozesse!$T$2:$T$125,0)),"") -> CP | D60: =IFERROR(INDEX(Prozesse!$H$2:$H$125,MATCH(1,Prozesse!$T$2:$T$125,0)),"") -> Verzögert | E60: =IFERROR(INDEX(Prozesse!$I$2:$I$125,MATCH(1,Prozesse!$T$2:$T$125,0)),"") -> 1 | F60: =IFERROR(INDEX(Prozesse!$K$2:$K$125,MATCH(1,Prozesse!$T$2:$T$125,0)),"") -> 46142 | G60: =IFERROR(INDEX(Prozesse!$O$2:$O$125,MATCH(1,Prozesse!$T$2:$T$125,0)),"") -> Mielenz Thomas (LMT)
B61: =IFERROR(INDEX(Prozesse!$B$2:$B$125,MATCH(2,Prozesse!$T$2:$T$125,0)),"") -> Approve IT demand | C61: =IFERROR(INDEX(Prozesse!$D$2:$D$125,MATCH(2,Prozesse!$T$2:$T$125,0)),"") -> CP | D61: =IFERROR(INDEX(Prozesse!$H$2:$H$125,MATCH(2,Prozesse!$T$2:$T$125,0)),"") -> Verzögert | E61: =IFERROR(INDEX(Prozesse!$I$2:$I$125,MATCH(2,Prozesse!$T$2:$T$125,0)),"") -> 1 | F61: =IFERROR(INDEX(Prozesse!$K$2:$K$125,MATCH(2,Prozesse!$T$2:$T$125,0)),"") -> 46112 | G61: =IFERROR(INDEX(Prozesse!$O$2:$O$125,MATCH(2,Prozesse!$T$2:$T$125,0)),"") -> Mielenz Thomas (LMT)
B62: =IFERROR(INDEX(Prozesse!$B$2:$B$125,MATCH(3,Prozesse!$T$2:$T$125,0)),"") -> Attract and hire employees | C62: =IFERROR(INDEX(Prozesse!$D$2:$D$125,MATCH(3,Prozesse!$T$2:$T$125,0)),"") -> SP | D62: =IFERROR(INDEX(Prozesse!$H$2:$H$125,MATCH(3,Prozesse!$T$2:$T$125,0)),"") -> Verzögert | E62: =IFERROR(INDEX(Prozesse!$I$2:$I$125,MATCH(3,Prozesse!$T$2:$T$125,0)),"") -> 0.18 | F62: =IFERROR(INDEX(Prozesse!$K$2:$K$125,MATCH(3,Prozesse!$T$2:$T$125,0)),"") -> 46387 | G62: =IFERROR(INDEX(Prozesse!$O$2:$O$125,MATCH(3,Prozesse!$T$2:$T$125,0)),"") -> Mielenz Thomas (LMT)
B63: =IFERROR(INDEX(Prozesse!$B$2:$B$125,MATCH(4,Prozesse!$T$2:$T$125,0)),"") -> Define solution target architecture | C63: =IFERROR(INDEX(Prozesse!$D$2:$D$125,MATCH(4,Prozesse!$T$2:$T$125,0)),"") -> CP | D63: =IFERROR(INDEX(Prozesse!$H$2:$H$125,MATCH(4,Prozesse!$T$2:$T$125,0)),"") -> Verzögert | E63: =IFERROR(INDEX(Prozesse!$I$2:$I$125,MATCH(4,Prozesse!$T$2:$T$125,0)),"") -> 0.5 | F63: =IFERROR(INDEX(Prozesse!$K$2:$K$125,MATCH(4,Prozesse!$T$2:$T$125,0)),"") -> 46195 | G63: =IFERROR(INDEX(Prozesse!$O$2:$O$125,MATCH(4,Prozesse!$T$2:$T$125,0)),"") -> Nussbaumer Florian (LBC)
B64: =IFERROR(INDEX(Prozesse!$B$2:$B$125,MATCH(5,Prozesse!$T$2:$T$125,0)),"") -> Ensure performance and conformance of IT services | C64: =IFERROR(INDEX(Prozesse!$D$2:$D$125,MATCH(5,Prozesse!$T$2:$T$125,0)),"") -> SP | D64: =IFERROR(INDEX(Prozesse!$H$2:$H$125,MATCH(5,Prozesse!$T$2:$T$125,0)),"") -> Verzögert | E64: =IFERROR(INDEX(Prozesse!$I$2:$I$125,MATCH(5,Prozesse!$T$2:$T$125,0)),"") -> 0 | F64: =IFERROR(INDEX(Prozesse!$K$2:$K$125,MATCH(5,Prozesse!$T$2:$T$125,0)),"") -> 0 | G64: =IFERROR(INDEX(Prozesse!$O$2:$O$125,MATCH(5,Prozesse!$T$2:$T$125,0)),"") -> Sint Rachel (LBH)
B65: =IFERROR(INDEX(Prozesse!$B$2:$B$125,MATCH(6,Prozesse!$T$2:$T$125,0)),"") -> Evaluate and qualify IT demand | C65: =IFERROR(INDEX(Prozesse!$D$2:$D$125,MATCH(6,Prozesse!$T$2:$T$125,0)),"") -> CP | D65: =IFERROR(INDEX(Prozesse!$H$2:$H$125,MATCH(6,Prozesse!$T$2:$T$125,0)),"") -> Verzögert | E65: =IFERROR(INDEX(Prozesse!$I$2:$I$125,MATCH(6,Prozesse!$T$2:$T$125,0)),"") -> 1 | F65: =IFERROR(INDEX(Prozesse!$K$2:$K$125,MATCH(6,Prozesse!$T$2:$T$125,0)),"") -> 46142 | G65: =IFERROR(INDEX(Prozesse!$O$2:$O$125,MATCH(6,Prozesse!$T$2:$T$125,0)),"") -> Mielenz Thomas (LMT)
B66: =IFERROR(INDEX(Prozesse!$B$2:$B$125,MATCH(7,Prozesse!$T$2:$T$125,0)),"") -> Handle IT service order | C66: =IFERROR(INDEX(Prozesse!$D$2:$D$125,MATCH(7,Prozesse!$T$2:$T$125,0)),"") -> CP | D66: =IFERROR(INDEX(Prozesse!$H$2:$H$125,MATCH(7,Prozesse!$T$2:$T$125,0)),"") -> Verzögert | E66: =IFERROR(INDEX(Prozesse!$I$2:$I$125,MATCH(7,Prozesse!$T$2:$T$125,0)),"") -> 0 | F66: =IFERROR(INDEX(Prozesse!$K$2:$K$125,MATCH(7,Prozesse!$T$2:$T$125,0)),"") -> 46190 | G66: =IFERROR(INDEX(Prozesse!$O$2:$O$125,MATCH(7,Prozesse!$T$2:$T$125,0)),"") -> Schnurrenberger Christoph (LIS-LIN)
B67: =IFERROR(INDEX(Prozesse!$B$2:$B$125,MATCH(8,Prozesse!$T$2:$T$125,0)),"") -> Implement and maintain IT job architecture | C67: =IFERROR(INDEX(Prozesse!$D$2:$D$125,MATCH(8,Prozesse!$T$2:$T$125,0)),"") -> SP | D67: =IFERROR(INDEX(Prozesse!$H$2:$H$125,MATCH(8,Prozesse!$T$2:$T$125,0)),"") -> Verzögert | E67: =IFERROR(INDEX(Prozesse!$I$2:$I$125,MATCH(8,Prozesse!$T$2:$T$125,0)),"") -> 0 | F67: =IFERROR(INDEX(Prozesse!$K$2:$K$125,MATCH(8,Prozesse!$T$2:$T$125,0)),"") -> 46173 | G67: =IFERROR(INDEX(Prozesse!$O$2:$O$125,MATCH(8,Prozesse!$T$2:$T$125,0)),"") -> Rollinger Alexander (LIS)
B68: =IFERROR(INDEX(Prozesse!$B$2:$B$125,MATCH(9,Prozesse!$T$2:$T$125,0)),"") -> Maintain IT glossary | C68: =IFERROR(INDEX(Prozesse!$D$2:$D$125,MATCH(9,Prozesse!$T$2:$T$125,0)),"") -> MP | D68: =IFERROR(INDEX(Prozesse!$H$2:$H$125,MATCH(9,Prozesse!$T$2:$T$125,0)),"") -> Verzögert | E68: =IFERROR(INDEX(Prozesse!$I$2:$I$125,MATCH(9,Prozesse!$T$2:$T$125,0)),"") -> 0.25 | F68: =IFERROR(INDEX(Prozesse!$K$2:$K$125,MATCH(9,Prozesse!$T$2:$T$125,0)),"") -> 46039 | G68: =IFERROR(INDEX(Prozesse!$O$2:$O$125,MATCH(9,Prozesse!$T$2:$T$125,0)),"") -> Mielenz Thomas (LMT)
B69: =IFERROR(INDEX(Prozesse!$B$2:$B$125,MATCH(10,Prozesse!$T$2:$T$125,0)),"") -> Manage HR4IT service demand | C69: =IFERROR(INDEX(Prozesse!$D$2:$D$125,MATCH(10,Prozesse!$T$2:$T$125,0)),"") -> SP | D69: =IFERROR(INDEX(Prozesse!$H$2:$H$125,MATCH(10,Prozesse!$T$2:$T$125,0)),"") -> Verzögert | E69: =IFERROR(INDEX(Prozesse!$I$2:$I$125,MATCH(10,Prozesse!$T$2:$T$125,0)),"") -> 0 | F69: =IFERROR(INDEX(Prozesse!$K$2:$K$125,MATCH(10,Prozesse!$T$2:$T$125,0)),"") -> 46203 | G69: =IFERROR(INDEX(Prozesse!$O$2:$O$125,MATCH(10,Prozesse!$T$2:$T$125,0)),"") -> Rollinger Alexander (LIS)
B70: =IFERROR(INDEX(Prozesse!$B$2:$B$125,MATCH(11,Prozesse!$T$2:$T$125,0)),"") -> Manage IT global orientation programme incl. job shadowing | C70: =IFERROR(INDEX(Prozesse!$D$2:$D$125,MATCH(11,Prozesse!$T$2:$T$125,0)),"") -> SP | D70: =IFERROR(INDEX(Prozesse!$H$2:$H$125,MATCH(11,Prozesse!$T$2:$T$125,0)),"") -> Verzögert | E70: =IFERROR(INDEX(Prozesse!$I$2:$I$125,MATCH(11,Prozesse!$T$2:$T$125,0)),"") -> 0 | F70: =IFERROR(INDEX(Prozesse!$K$2:$K$125,MATCH(11,Prozesse!$T$2:$T$125,0)),"") -> 46204 | G70: =IFERROR(INDEX(Prozesse!$O$2:$O$125,MATCH(11,Prozesse!$T$2:$T$125,0)),"") -> Mielenz Thomas (LMT)
B71: =IFERROR(INDEX(Prozesse!$B$2:$B$125,MATCH(12,Prozesse!$T$2:$T$125,0)),"") -> Manage IT knowledge | C71: =IFERROR(INDEX(Prozesse!$D$2:$D$125,MATCH(12,Prozesse!$T$2:$T$125,0)),"") -> SP | D71: =IFERROR(INDEX(Prozesse!$H$2:$H$125,MATCH(12,Prozesse!$T$2:$T$125,0)),"") -> Verzögert | E71: =IFERROR(INDEX(Prozesse!$I$2:$I$125,MATCH(12,Prozesse!$T$2:$T$125,0)),"") -> 1 | F71: =IFERROR(INDEX(Prozesse!$K$2:$K$125,MATCH(12,Prozesse!$T$2:$T$125,0)),"") -> 46203 | G71: =IFERROR(INDEX(Prozesse!$O$2:$O$125,MATCH(12,Prozesse!$T$2:$T$125,0)),"") -> Sint Rachel (LBH)
B72: =IFERROR(INDEX(Prozesse!$B$2:$B$125,MATCH(13,Prozesse!$T$2:$T$125,0)),"") -> Manage IT project portfolio | C72: =IFERROR(INDEX(Prozesse!$D$2:$D$125,MATCH(13,Prozesse!$T$2:$T$125,0)),"") -> MP | D72: =IFERROR(INDEX(Prozesse!$H$2:$H$125,MATCH(13,Prozesse!$T$2:$T$125,0)),"") -> Verzögert | E72: =IFERROR(INDEX(Prozesse!$I$2:$I$125,MATCH(13,Prozesse!$T$2:$T$125,0)),"") -> 1 | F72: =IFERROR(INDEX(Prozesse!$K$2:$K$125,MATCH(13,Prozesse!$T$2:$T$125,0)),"") -> 46173 | G72: =IFERROR(INDEX(Prozesse!$O$2:$O$125,MATCH(13,Prozesse!$T$2:$T$125,0)),"") -> Rollinger Alexander (LIS)
B73: =IFERROR(INDEX(Prozesse!$B$2:$B$125,MATCH(14,Prozesse!$T$2:$T$125,0)),"") -> Manage IT service provision request | C73: =IFERROR(INDEX(Prozesse!$D$2:$D$125,MATCH(14,Prozesse!$T$2:$T$125,0)),"") -> CP | D73: =IFERROR(INDEX(Prozesse!$H$2:$H$125,MATCH(14,Prozesse!$T$2:$T$125,0)),"") -> Verzögert | E73: =IFERROR(INDEX(Prozesse!$I$2:$I$125,MATCH(14,Prozesse!$T$2:$T$125,0)),"") -> 0 | F73: =IFERROR(INDEX(Prozesse!$K$2:$K$125,MATCH(14,Prozesse!$T$2:$T$125,0)),"") -> 46190 | G73: =IFERROR(INDEX(Prozesse!$O$2:$O$125,MATCH(14,Prozesse!$T$2:$T$125,0)),"") -> Schnurrenberger Christoph (LIS-LIN)
B74: =IFERROR(INDEX(Prozesse!$B$2:$B$125,MATCH(15,Prozesse!$T$2:$T$125,0)),"") -> Manage IT skills | C74: =IFERROR(INDEX(Prozesse!$D$2:$D$125,MATCH(15,Prozesse!$T$2:$T$125,0)),"") -> SP | D74: =IFERROR(INDEX(Prozesse!$H$2:$H$125,MATCH(15,Prozesse!$T$2:$T$125,0)),"") -> Verzögert | E74: =IFERROR(INDEX(Prozesse!$I$2:$I$125,MATCH(15,Prozesse!$T$2:$T$125,0)),"") -> 0 | F74: =IFERROR(INDEX(Prozesse!$K$2:$K$125,MATCH(15,Prozesse!$T$2:$T$125,0)),"") -> 46568 | G74: =IFERROR(INDEX(Prozesse!$O$2:$O$125,MATCH(15,Prozesse!$T$2:$T$125,0)),"") -> Mielenz Thomas (LMT)

Sheet Prozesse
A1: Nr | B1: Prozess | C1: Pfad | D1: Gruppe | E1: Initiative | F1: L1-Prozess | G1: Ebene | H1: Status | I1: Fortschritt | J1: Start | K1: Ende | L1: Dauer (T) | M1: Elaboration | N1: Initiative Lead | O1: Process Manager | P1: Consultant | Q1: Überfällig | R1: In Implementierung | S1: Treffer | T1: Rang
A2: 1 | B2: Analyse architecture impact | C2: Plan IT service › Evaluate and qualify IT demand › Analyse architecture impact | D2: CP | E2: Corporate IT body | F2: Plan IT service | G2: L3 | H2: Verzögert | I2: 1 | J2: 45870 | K2: 46142 | L2: 195 | M2: Abgeschlossen | N2: Pernet Benoit (LEC)) | O2: Mielenz Thomas (LMT) | P2: Kunz Christina (LIS-MHP) | Q2: =IF(AND(K2<>"",K2<Cockpit!$H$6,H2<>"Abgeschlossen"),1,0) -> 1 | R2: 1 | S2: =IF(AND(OR(Cockpit!$B$6="(Alle)",D2=Cockpit!$B$6),OR(Cockpit!$C$6="(Alle)",E2=Cockpit!$C$6),OR(Cockpit!$D$6="(Alle)",F2=Cockpit!$D$6),OR(Cockpit!$E$6="(Alle)",G2=Cockpit!$E$6),OR(Cockpit!$F$6="(Alle)",H2=Cockpit!$F$6),OR(Cockpit!$G$6="(Alle)",O2=Cockpit!$G$6)),1,0) -> 1 | T2: =IF(S2=1,SUM($S$2:S2),"") -> 1
A3: 2 | B3: Approve IT demand | C3: Plan IT service › Approve IT demand | D3: CP | E3: Corporate IT body | F3: Plan IT service | G3: L2 | H3: Verzögert | I3: 1 | J3: 45870 | K3: 46112 | L3: 1 | M3: Abgeschlossen | N3: Spieth Tina (LIS) | O3: Mielenz Thomas (LMT) | P3: Kunz Christina (LIS-MHP) | Q3: =IF(AND(K3<>"",K3<Cockpit!$H$6,H3<>"Abgeschlossen"),1,0) -> 1 | R3: 1 | S3: =IF(AND(OR(Cockpit!$B$6="(Alle)",D3=Cockpit!$B$6),OR(Cockpit!$C$6="(Alle)",E3=Cockpit!$C$6),OR(Cockpit!$D$6="(Alle)",F3=Cockpit!$D$6),OR(Cockpit!$E$6="(Alle)",G3=Cockpit!$E$6),OR(Cockpit!$F$6="(Alle)",H3=Cockpit!$F$6),OR(Cockpit!$G$6="(Alle)",O3=Cockpit!$G$6)),1,0) -> 1 | T3: =IF(S3=1,SUM($S$2:S3),"") -> 2
A4: 3 | B4: Attract and hire employees | C4: Provide and develop IT workforce › Attract and hire employees | D4: SP | E4: HR initiatives for IT | F4: Provide and develop IT workforce | G4: L2 | H4: Verzögert | I4: 0.18 | J4: 45931 | K4: 46387 | L4: 327 | M4: In Arbeit | N4: Kiesewetter Ivana (LIS) | O4: Mielenz Thomas (LMT) | P4: Chen Leilei (LIS-BPMO), Hynek Tobias (LIS) | Q4: =IF(AND(K4<>"",K4<Cockpit!$H$6,H4<>"Abgeschlossen"),1,0) -> 0 | R4: 0 | S4: =IF(AND(OR(Cockpit!$B$6="(Alle)",D4=Cockpit!$B$6),OR(Cockpit!$C$6="(Alle)",E4=Cockpit!$C$6),OR(Cockpit!$D$6="(Alle)",F4=Cockpit!$D$6),OR(Cockpit!$E$6="(Alle)",G4=Cockpit!$E$6),OR(Cockpit!$F$6="(Alle)",H4=Cockpit!$F$6),OR(Cockpit!$G$6="(Alle)",O4=Cockpit!$G$6)),1,0) -> 1 | T4: =IF(S4=1,SUM($S$2:S4),"") -> 3
A5: 4 | B5: Define solution target architecture | C5: Build IT Service › Design IT service › Define solution target architecture | D5: CP | E5: Architecture management | F5: Build IT Service | G5: L3 | H5: Verzögert | I5: 0.5 | J5: 46036 | K5: 46195 | L5: 114 | M5: In Arbeit | N5: Hammer Marco (AER) | O5: Nussbaumer Florian (LBC) | P5: Hoermann Patrick (LLI) | Q5: =IF(AND(K5<>"",K5<Cockpit!$H$6,H5<>"Abgeschlossen"),1,0) -> 1 | R5: 0 | S5: =IF(AND(OR(Cockpit!$B$6="(Alle)",D5=Cockpit!$B$6),OR(Cockpit!$C$6="(Alle)",E5=Cockpit!$C$6),OR(Cockpit!$D$6="(Alle)",F5=Cockpit!$D$6),OR(Cockpit!$E$6="(Alle)",G5=Cockpit!$E$6),OR(Cockpit!$F$6="(Alle)",H5=Cockpit!$F$6),OR(Cockpit!$G$6="(Alle)",O5=Cockpit!$G$6)),1,0) -> 1 | T5: =IF(S5=1,SUM($S$2:S5),"") -> 4
A6: 5 | B6: Ensure performance and conformance of IT services | C6: Ensure performance and conformance of IT services | D6: SP | E6: ITSM | F6: Ensure performance and conformance of IT services | G6: L1 | H6: Verzögert | I6: 0 | M6: Verzögert | N6: – | O6: Sint Rachel (LBH) | P6: Schroeder Michael (LIS) | Q6: =IF(AND(K6<>"",K6<Cockpit!$H$6,H6<>"Abgeschlossen"),1,0) -> 0 | R6: 0 | S6: =IF(AND(OR(Cockpit!$B$6="(Alle)",D6=Cockpit!$B$6),OR(Cockpit!$C$6="(Alle)",E6=Cockpit!$C$6),OR(Cockpit!$D$6="(Alle)",F6=Cockpit!$D$6),OR(Cockpit!$E$6="(Alle)",G6=Cockpit!$E$6),OR(Cockpit!$F$6="(Alle)",H6=Cockpit!$F$6),OR(Cockpit!$G$6="(Alle)",O6=Cockpit!$G$6)),1,0) -> 1 | T6: =IF(S6=1,SUM($S$2:S6),"") -> 5
A7: 6 | B7: Evaluate and qualify IT demand | C7: Plan IT service › Evaluate and qualify IT demand | D7: CP | E7: Corporate IT body | F7: Plan IT service | G7: L2 | H7: Verzögert | I7: 1 | J7: 45870 | K7: 46142 | L7: 195 | M7: Abgeschlossen | N7: Spieth Tina (LIS) | O7: Mielenz Thomas (LMT) | P7: Kunz Christina (LIS-MHP) | Q7: =IF(AND(K7<>"",K7<Cockpit!$H$6,H7<>"Abgeschlossen"),1,0) -> 1 | R7: 1 | S7: =IF(AND(OR(Cockpit!$B$6="(Alle)",D7=Cockpit!$B$6),OR(Cockpit!$C$6="(Alle)",E7=Cockpit!$C$6),OR(Cockpit!$D$6="(Alle)",F7=Cockpit!$D$6),OR(Cockpit!$E$6="(Alle)",G7=Cockpit!$E$6),OR(Cockpit!$F$6="(Alle)",H7=Cockpit!$F$6),OR(Cockpit!$G$6="(Alle)",O7=Cockpit!$G$6)),1,0) -> 1 | T7: =IF(S7=1,SUM($S$2:S7),"") -> 6
A8: 7 | B8: Handle IT service order | C8: Deliver IT service › Handle IT service order | D8: CP | E8: ITSM | F8: Deliver IT service | G8: L2 | H8: Verzögert | I8: 0 | J8: 46113 | K8: 46190 | L8: 56 | M8: Verzögert | N8: – | O8: Schnurrenberger Christoph (LIS-LIN) | P8: – | Q8: =IF(AND(K8<>"",K8<Cockpit!$H$6,H8<>"Abgeschlossen"),1,0) -> 1 | R8: 0 | S8: =IF(AND(OR(Cockpit!$B$6="(Alle)",D8=Cockpit!$B$6),OR(Cockpit!$C$6="(Alle)",E8=Cockpit!$C$6),OR(Cockpit!$D$6="(Alle)",F8=Cockpit!$D$6),OR(Cockpit!$E$6="(Alle)",G8=Cockpit!$E$6),OR(Cockpit!$F$6="(Alle)",H8=Cockpit!$F$6),OR(Cockpit!$G$6="(Alle)",O8=Cockpit!$G$6)),1,0) -> 1 | T8: =IF(S8=1,SUM($S$2:S8),"") -> 7
A9: 8 | B9: Implement and maintain IT job architecture | C9: Provide and develop IT workforce › Manage HR4IT strategy, governane and framework › Implement and maintain IT job architecture | D9: SP | E9: HR initiatives for IT | F9: Provide and develop IT workforce | G9: L3 | H9: Verzögert | I9: 0 | J9: 45946 | K9: 46173 | L9: 162 | M9: Verzögert | N9: Amelang Nicole (LIS) | O9: Rollinger Alexander (LIS) | P9: Chen Leilei (LIS-BPMO), Hynek Tobias (LIS) | Q9: =IF(AND(K9<>"",K9<Cockpit!$H$6,H9<>"Abgeschlossen"),1,0) -> 1 | R9: 0 | S9: =IF(AND(OR(Cockpit!$B$6="(Alle)",D9=Cockpit!$B$6),OR(Cockpit!$C$6="(Alle)",E9=Cockpit!$C$6),OR(Cockpit!$D$6="(Alle)",F9=Cockpit!$D$6),OR(Cockpit!$E$6="(Alle)",G9=Cockpit!$E$6),OR(Cockpit!$F$6="(Alle)",H9=Cockpit!$F$6),OR(Cockpit!$G$6="(Alle)",O9=Cockpit!$G$6)),1,0) -> 1 | T9: =IF(S9=1,SUM($S$2:S9),"") -> 8
A10: 9 | B10: Maintain IT glossary | C10: Manage IT governance framework › Maintain IT glossary | D10: MP | E10: Corporate IT body | F10: Manage IT governance framework | G10: L2 | H10: Verzögert | I10: 0.25 | J10: 46029 | K10: 46039 | L10: 8 | M10: Ohne Angabe | N10: Felder Max (LLI) | O10: Mielenz Thomas (LMT) | P10: Kunz Christina (LIS-MHP) | Q10: =IF(AND(K10<>"",K10<Cockpit!$H$6,H10<>"Abgeschlossen"),1,0) -> 1 | R10: 0 | S10: =IF(AND(OR(Cockpit!$B$6="(Alle)",D10=Cockpit!$B$6),OR(Cockpit!$C$6="(Alle)",E10=Cockpit!$C$6),OR(Cockpit!$D$6="(Alle)",F10=Cockpit!$D$6),OR(Cockpit!$E$6="(Alle)",G10=Cockpit!$E$6),OR(Cockpit!$F$6="(Alle)",H10=Cockpit!$F$6),OR(Cockpit!$G$6="(Alle)",O10=Cockpit!$G$6)),1,0) -> 1 | T10: =IF(S10=1,SUM($S$2:S10),"") -> 9
A11: 10 | B11: Manage HR4IT service demand | C11: Provide and develop IT workforce › Manage HR4IT strategy, governane and framework › Manage HR4IT service demand | D11: SP | E11: HR initiatives for IT | F11: Provide and develop IT workforce | G11: L3 | H11: Verzögert | I11: 0 | J11: 45931 | K11: 46203 | L11: 195 | M11: Verzögert | N11: Amelang Nicole (LIS) | O11: Rollinger Alexander (LIS) | P11: Chen Leilei (LIS-BPMO), Hynek Tobias (LIS) | Q11: =IF(AND(K11<>"",K11<Cockpit!$H$6,H11<>"Abgeschlossen"),1,0) -> 1 | R11: 0 | S11: =IF(AND(OR(Cockpit!$B$6="(Alle)",D11=Cockpit!$B$6),OR(Cockpit!$C$6="(Alle)",E11=Cockpit!$C$6),OR(Cockpit!$D$6="(Alle)",F11=Cockpit!$D$6),OR(Cockpit!$E$6="(Alle)",G11=Cockpit!$E$6),OR(Cockpit!$F$6="(Alle)",H11=Cockpit!$F$6),OR(Cockpit!$G$6="(Alle)",O11=Cockpit!$G$6)),1,0) -> 1 | T11: =IF(S11=1,SUM($S$2:S11),"") -> 10
A12: 11 | B12: Manage IT global orientation programme incl. job shadowing | C12: Provide and develop IT workforce › Perform, learn and grow › Manage IT global orientation programme incl. job shadowing | D12: SP | E12: HR initiatives for IT | F12: Provide and develop IT workforce | G12: L3 | H12: Verzögert | I12: 0 | J12: 46037 | K12: 46204 | L12: 120 | M12: Verzögert | N12: Grabmair Melanie (LIS) | O12: Mielenz Thomas (LMT) | P12: Chen Leilei (LIS-BPMO), Hynek Tobias (LIS) | Q12: =IF(AND(K12<>"",K12<Cockpit!$H$6,H12<>"Abgeschlossen"),1,0) -> 1 | R12: 0 | S12: =IF(AND(OR(Cockpit!$B$6="(Alle)",D12=Cockpit!$B$6),OR(Cockpit!$C$6="(Alle)",E12=Cockpit!$C$6),OR(Cockpit!$D$6="(Alle)",F12=Cockpit!$D$6),OR(Cockpit!$E$6="(Alle)",G12=Cockpit!$E$6),OR(Cockpit!$F$6="(Alle)",H12=Cockpit!$F$6),OR(Cockpit!$G$6="(Alle)",O12=Cockpit!$G$6)),1,0) -> 1 | T12: =IF(S12=1,SUM($S$2:S12),"") -> 11
A13: 12 | B13: Manage IT knowledge | C13: Manage IT knowledge | D13: SP | E13: ITSM | F13: Manage IT knowledge | G13: L1 | H13: Verzögert | I13: 1 | J13: 46042 | K13: 46203 | L13: 116 | M13: Abgeschlossen | N13: Kuerschner Philipp (LIS) | O13: Sint Rachel (LBH) | P13: Schroeder Michael (LIS) | Q13: =IF(AND(K13<>"",K13<Cockpit!$H$6,H13<>"Abgeschlossen"),1,0) -> 1 | R13: 1 | S13: =IF(AND(OR(Cockpit!$B$6="(Alle)",D13=Cockpit!$B$6),OR(Cockpit!$C$6="(Alle)",E13=Cockpit!$C$6),OR(Cockpit!$D$6="(Alle)",F13=Cockpit!$D$6),OR(Cockpit!$E$6="(Alle)",G13=Cockpit!$E$6),OR(Cockpit!$F$6="(Alle)",H13=Cockpit!$F$6),OR(Cockpit!$G$6="(Alle)",O13=Cockpit!$G$6)),1,0) -> 1 | T13: =IF(S13=1,SUM($S$2:S13),"") -> 12
A14: 13 | B14: Manage IT project portfolio | C14: Manage IT portfolio › Manage IT project portfolio | D14: MP | E14: IT project management | F14: Manage IT portfolio | G14: L2 | H14: Verzögert | I14: 1 | J14: 45971 | K14: 46173 | L14: 145 | M14: Abgeschlossen | N14: Mühlbacher Christian (LIS) | O14: Rollinger Alexander (LIS) | P14: Frank Maren (LIS) | Q14: =IF(AND(K14<>"",K14<Cockpit!$H$6,H14<>"Abgeschlossen"),1,0) -> 1 | R14: 0 | S14: =IF(AND(OR(Cockpit!$B$6="(Alle)",D14=Cockpit!$B$6),OR(Cockpit!$C$6="(Alle)",E14=Cockpit!$C$6),OR(Cockpit!$D$6="(Alle)",F14=Cockpit!$D$6),OR(Cockpit!$E$6="(Alle)",G14=Cockpit!$E$6),OR(Cockpit!$F$6="(Alle)",H14=Cockpit!$F$6),OR(Cockpit!$G$6="(Alle)",O14=Cockpit!$G$6)),1,0) -> 1 | T14: =IF(S14=1,SUM($S$2:S14),"") -> 13
A15: 14 | B15: Manage IT service provision request | C15: Deliver IT service › Manage IT service provision request | D15: CP | E15: ITSM | F15: Deliver IT service | G15: L2 | H15: Verzögert | I15: 0 | J15: 46113 | K15: 46190 | L15: 56 | M15: Verzögert | N15: – | O15: Schnurrenberger Christoph (LIS-LIN) | P15: – | Q15: =IF(AND(K15<>"",K15<Cockpit!$H$6,H15<>"Abgeschlossen"),1,0) -> 1 | R15: 0 | S15: =IF(AND(OR(Cockpit!$B$6="(Alle)",D15=Cockpit!$B$6),OR(Cockpit!$C$6="(Alle)",E15=Cockpit!$C$6),OR(Cockpit!$D$6="(Alle)",F15=Cockpit!$D$6),OR(Cockpit!$E$6="(Alle)",G15=Cockpit!$E$6),OR(Cockpit!$F$6="(Alle)",H15=Cockpit!$F$6),OR(Cockpit!$G$6="(Alle)",O15=Cockpit!$G$6)),1,0) -> 1 | T15: =IF(S15=1,SUM($S$2:S15),"") -> 14
A16: 15 | B16: Manage IT skills | C16: Provide and develop IT workforce › Perform, learn and grow › Manage IT skills | D16: SP | E16: HR initiatives for IT | F16: Provide and develop IT workforce | G16: L3 | H16: Verzögert | I16: 0 | J16: 46023 | K16: 46568 | L16: 390 | M16: Verzögert | N16: Grabmair Melanie (LIS) | O16: Mielenz Thomas (LMT) | P16: Chen Leilei (LIS-BPMO), Hynek Tobias (LIS) | Q16: =IF(AND(K16<>"",K16<Cockpit!$H$6,H16<>"Abgeschlossen"),1,0) -> 0 | R16: 0 | S16: =IF(AND(OR(Cockpit!$B$6="(Alle)",D16=Cockpit!$B$6),OR(Cockpit!$C$6="(Alle)",E16=Cockpit!$C$6),OR(Cockpit!$D$6="(Alle)",F16=Cockpit!$D$6),OR(Cockpit!$E$6="(Alle)",G16=Cockpit!$E$6),OR(Cockpit!$F$6="(Alle)",H16=Cockpit!$F$6),OR(Cockpit!$G$6="(Alle)",O16=Cockpit!$G$6)),1,0) -> 1 | T16: =IF(S16=1,SUM($S$2:S16),"") -> 15
A17: 16 | B17: Manage IT stakeholder relationships | C17: Manage IT stakeholder relationships | D17: MP | E17: Corporate IT body | F17: Manage IT stakeholder relationships | G17: L1 | H17: Verzögert | I17: 0 | J17: 46113 | K17: 46379 | L17: 191 | M17: Verzögert | N17: Felder Max (LLI) | O17: Mielenz Thomas (LMT) | P17: Kreis Andreas (LLI) | Q17: =IF(AND(K17<>"",K17<Cockpit!$H$6,H17<>"Abgeschlossen"),1,0) -> 0 | R17: 0 | S17: =IF(AND(OR(Cockpit!$B$6="(Alle)",D17=Cockpit!$B$6),OR(Cockpit!$C$6="(Alle)",E17=Cockpit!$C$6),OR(Cockpit!$D$6="(Alle)",F17=Cockpit!$D$6),OR(Cockpit!$E$6="(Alle)",G17=Cockpit!$E$6),OR(Cockpit!$F$6="(Alle)",H17=Cockpit!$F$6),OR(Cockpit!$G$6="(Alle)",O17=Cockpit!$G$6)),1,0) -> 1 | T17: =IF(S17=1,SUM($S$2:S17),"") -> 16
A18: 17 | B18: Manage continuous improvement | C18: Manage IT processes and continuous improvement › Manage continuous improvement | D18: MP | E18: ITSM | F18: Manage IT processes and continuous improvement | G18: L2 | H18: Verzögert | I18: 0 | J18: 45931 | K18: 46052 | L18: 88 | M18: Verzögert | N18: Kuerschner Philipp (LIS) | O18: Reiner Heiko (HAU-ITSA) | P18: Boehme Matthias (LIS-BPMO), Rollinger Alexander (LIS) | Q18: =IF(AND(K18<>"",K18<Cockpit!$H$6,H18<>"Abgeschlossen"),1,0) -> 1 | R18: 0 | S18: =IF(AND(OR(Cockpit!$B$6="(Alle)",D18=Cockpit!$B$6),OR(Cockpit!$C$6="(Alle)",E18=Cockpit!$C$6),OR(Cockpit!$D$6="(Alle)",F18=Cockpit!$D$6),OR(Cockpit!$E$6="(Alle)",G18=Cockpit!$E$6),OR(Cockpit!$F$6="(Alle)",H18=Cockpit!$F$6),OR(Cockpit!$G$6="(Alle)",O18=Cockpit!$G$6)),1,0) -> 1 | T18: =IF(S18=1,SUM($S$2:S18),"") -> 17
... A29: 28 | B29: Run IT service | C29: Run IT service | D29: CP | E29: ITSM | F29: Run IT service | G29: L1 | H29: Verzögert | I29: 0.17 | J29: 45945 | K29: 46290 | L29: 248 | M29: Verzögert | N29: Oey Kai (LIS) | O29: Sint Rachel (LBH) | P29: Schroeder Michael (LIS), Boehme Matthias (LIS-BPMO) | Q29: =IF(AND(K29<>"",K29<Cockpit!$H$6,H29<>"Abgeschlossen"),1,0) -> 0 | R29: 0 | S29: =IF(AND(OR(Cockpit!$B$6="(Alle)",D29=Cockpit!$B$6),OR(Cockpit!$C$6="(Alle)",E29=Cockpit!$C$6),OR(Cockpit!$D$6="(Alle)",F29=Cockpit!$D$6),OR(Cockpit!$E$6="(Alle)",G29=Cockpit!$E$6),OR(Cockpit!$F$6="(Alle)",H29=Cockpit!$F$6),OR(Cockpit!$G$6="(Alle)",O29=Cockpit!$G$6)),1,0) -> 1 | T29: =IF(S29=1,SUM($S$2:S29),"") -> 28
A30: 29 | B30: Strategic architecture process | C30: Manage enterprise architecture › Strategic architecture process | D30: MP | E30: Corporate IT body | F30: Manage enterprise architecture | G30: L2 | H30: Verzögert | I30: 0 | J30: 45946 | K30: 46142 | M30: Verzögert | N30: – | O30: – | P30: – | Q30: =IF(AND(K30<>"",K30<Cockpit!$H$6,H30<>"Abgeschlossen"),1,0) -> 1 | R30: 0 | S30: =IF(AND(OR(Cockpit!$B$6="(Alle)",D30=Cockpit!$B$6),OR(Cockpit!$C$6="(Alle)",E30=Cockpit!$C$6),OR(Cockpit!$D$6="(Alle)",F30=Cockpit!$D$6),OR(Cockpit!$E$6="(Alle)",G30=Cockpit!$E$6),OR(Cockpit!$F$6="(Alle)",H30=Cockpit!$F$6),OR(Cockpit!$G$6="(Alle)",O30=Cockpit!$G$6)),1,0) -> 1 | T30: =IF(S30=1,SUM($S$2:S30),"") -> 29
A31: 30 | B31: Apply cost model to calculate service cost per unit | C31: Manage and control IT financials › Model and allocate IT costs › Apply cost model to calculate service cost per unit | D31: MP | E31: IT planning and steering | F31: Manage and control IT financials | G31: L3 | H31: In Arbeit | I31: 0.5 | J31: 45945 | M31: Ohne Angabe | N31: Frank Nicole (LIS) | O31: Moser Mario (LIS-LAH) | P31: Hynek Tobias (LIS), Kreis Andreas (LLI) | Q31: =IF(AND(K31<>"",K31<Cockpit!$H$6,H31<>"Abgeschlossen"),1,0) -> 0 | R31: 0 | S31: =IF(AND(OR(Cockpit!$B$6="(Alle)",D31=Cockpit!$B$6),OR(Cockpit!$C$6="(Alle)",E31=Cockpit!$C$6),OR(Cockpit!$D$6="(Alle)",F31=Cockpit!$D$6),OR(Cockpit!$E$6="(Alle)",G31=Cockpit!$E$6),OR(Cockpit!$F$6="(Alle)",H31=Cockpit!$F$6),OR(Cockpit!$G$6="(Alle)",O31=Cockpit!$G$6)),1,0) -> 1 | T31: =IF(S31=1,SUM($S$2:S31),"") -> 30
A32: 31 | B32: Approve and communicate budget plan | C32: Manage and control IT financials › Create and maintain IT budgets › Approve and communicate budget plan | D32: MP | E32: IT planning and steering | F32: Manage and control IT financials | G32: L3 | H32: In Arbeit | I32: 0.5 | J32: 45945 | M32: Ohne Angabe | N32: Frank Nicole (LIS) | O32: Mielenz Thomas (LMT) | P32: Hynek Tobias (LIS), Kreis Andreas (LLI) | Q32: =IF(AND(K32<>"",K32<Cockpit!$H$6,H32<>"Abgeschlossen"),1,0) -> 0 | R32: 0 | S32: =IF(AND(OR(Cockpit!$B$6="(Alle)",D32=Cockpit!$B$6),OR(Cockpit!$C$6="(Alle)",E32=Cockpit!$C$6),OR(Cockpit!$D$6="(Alle)",F32=Cockpit!$D$6),OR(Cockpit!$E$6="(Alle)",G32=Cockpit!$E$6),OR(Cockpit!$F$6="(Alle)",H32=Cockpit!$F$6),OR(Cockpit!$G$6="(Alle)",O32=Cockpit!$G$6)),1,0) -> 1 | T32: =IF(S32=1,SUM($S$2:S32),"") -> 31
A33: 32 | B33: Build IT Service | C33: Build IT Service | D33: CP | E33: ITSM | F33: Build IT Service | G33: L1 | H33: In Arbeit | I33: 0.41 | M33: Ohne Angabe | N33: Dalek Martin (LIS) | O33: Wiehe Alexander (COB) | P33: Kunz Christina (LIS-MHP) | Q33: =IF(AND(K33<>"",K33<Cockpit!$H$6,H33<>"Abgeschlossen"),1,0) -> 0 | R33: 0 | S33: =IF(AND(OR(Cockpit!$B$6="(Alle)",D33=Cockpit!$B$6),OR(Cockpit!$C$6="(Alle)",E33=Cockpit!$C$6),OR(Cockpit!$D$6="(Alle)",F33=Cockpit!$D$6),OR(Cockpit!$E$6="(Alle)",G33=Cockpit!$E$6),OR(Cockpit!$F$6="(Alle)",H33=Cockpit!$F$6),OR(Cockpit!$G$6="(Alle)",O33=Cockpit!$G$6)),1,0) -> 1 | T33: =IF(S33=1,SUM($S$2:S33),"") -> 32
A34: 33 | B34: Collect and consolidate budget from stakeholders | C34: Manage and control IT financials › Create and maintain IT budgets › Collect and consolidate budget from stakeholders | D34: MP | E34: IT planning and steering | F34: Manage and control IT financials | G34: L3 | H34: In Arbeit | I34: 0.5 | J34: 45945 | M34: Ohne Angabe | N34: Frank Nicole (LIS) | O34: Mielenz Thomas (LMT) | P34: Hynek Tobias (LIS), Kreis Andreas (LLI) | Q34: =IF(AND(K34<>"",K34<Cockpit!$H$6,H34<>"Abgeschlossen"),1,0) -> 0 | R34: 0 | S34: =IF(AND(OR(Cockpit!$B$6="(Alle)",D34=Cockpit!$B$6),OR(Cockpit!$C$6="(Alle)",E34=Cockpit!$C$6),OR(Cockpit!$D$6="(Alle)",F34=Cockpit!$D$6),OR(Cockpit!$E$6="(Alle)",G34=Cockpit!$E$6),OR(Cockpit!$F$6="(Alle)",H34=Cockpit!$F$6),OR(Cockpit!$G$6="(Alle)",O34=Cockpit!$G$6)),1,0) -> 1 | T34: =IF(S34=1,SUM($S$2:S34),"") -> 33
A35: 34 | B35: Compare actual cost to budget forecast | C35: Manage and control IT financials › Manage IT costs › Compare actual cost to budget forecast | D35: MP | E35: IT planning and steering | F35: Manage and control IT financials | G35: L3 | H35: In Arbeit | I35: 0.5 | J35: 45945 | M35: Ohne Angabe | N35: Frank Nicole (LIS) | O35: Moser Mario (LIS-LAH) | P35: Hynek Tobias (LIS), Kreis Andreas (LLI) | Q35: =IF(AND(K35<>"",K35<Cockpit!$H$6,H35<>"Abgeschlossen"),1,0) -> 0 | R35: 0 | S35: =IF(AND(OR(Cockpit!$B$6="(Alle)",D35=Cockpit!$B$6),OR(Cockpit!$C$6="(Alle)",E35=Cockpit!$C$6),OR(Cockpit!$D$6="(Alle)",F35=Cockpit!$D$6),OR(Cockpit!$E$6="(Alle)",G35=Cockpit!$E$6),OR(Cockpit!$F$6="(Alle)",H35=Cockpit!$F$6),OR(Cockpit!$G$6="(Alle)",O35=Cockpit!$G$6)),1,0) -> 1 | T35: =IF(S35=1,SUM($S$2:S35),"") -> 34
A36: 35 | B36: Create and maintain IT budgets | C36: Manage and control IT financials › Create and maintain IT budgets | D36: MP | E36: IT planning and steering | F36: Manage and control IT financials | G36: L2 | H36: In Arbeit | I36: 0.5 | J36: 45945 | M36: Ohne Angabe | N36: Frank Nicole (LIS) | O36: Mielenz Thomas (LMT) | P36: Hynek Tobias (LIS), Kreis Andreas (LLI) | Q36: =IF(AND(K36<>"",K36<Cockpit!$H$6,H36<>"Abgeschlossen"),1,0) -> 0 | R36: 0 | S36: =IF(AND(OR(Cockpit!$B$6="(Alle)",D36=Cockpit!$B$6),OR(Cockpit!$C$6="(Alle)",E36=Cockpit!$C$6),OR(Cockpit!$D$6="(Alle)",F36=Cockpit!$D$6),OR(Cockpit!$E$6="(Alle)",G36=Cockpit!$E$6),OR(Cockpit!$F$6="(Alle)",H36=Cockpit!$F$6),OR(Cockpit!$G$6="(Alle)",O36=Cockpit!$G$6)),1,0) -> 1 | T36: =IF(S36=1,SUM($S$2:S36),"") -> 35
A37: 36 | B37: Create, approve and publish trainings for IT workforce within IT Training Catalogue | C37: Provide and develop IT workforce › Perform, learn and grow › Create, approve and publish trainings for IT workforce within IT Training Catalogue | D37: SP | E37: HR initiatives for IT | F37: Provide and develop IT workforce | G37: L3 | H37: In Arbeit | I37: 0.5 | J37: 45931 | K37: 46142 | L37: 152 | M37: In Arbeit | N37: Grabmair Melanie (LIS) | O37: Mielenz Thomas (LMT) | P37: Chen Leilei (LIS-BPMO), Hynek Tobias (LIS) | Q37: =IF(AND(K37<>"",K37<Cockpit!$H$6,H37<>"Abgeschlossen"),1,0) -> 1 | R37: 0 | S37: =IF(AND(OR(Cockpit!$B$6="(Alle)",D37=Cockpit!$B$6),OR(Cockpit!$C$6="(Alle)",E37=Cockpit!$C$6),OR(Cockpit!$D$6="(Alle)",F37=Cockpit!$D$6),OR(Cockpit!$E$6="(Alle)",G37=Cockpit!$E$6),OR(Cockpit!$F$6="(Alle)",H37=Cockpit!$F$6),OR(Cockpit!$G$6="(Alle)",O37=Cockpit!$G$6)),1,0) -> 1 | T37: =IF(S37=1,SUM($S$2:S37),"") -> 36
A38: 37 | B38: DC/DCC/MSC IT-compliance | C38: Manage IT risks and compliance › Manage IT compliance › DC/DCC/MSC IT-compliance | D38: MP | E38: Central area (Jan Müskens) | F38: Manage IT risks and compliance | G38: L3 | H38: In Arbeit | I38: 0.25 | J38: 45931 | K38: 46295 | L38: 261 | M38: In Arbeit | N38: Mueskens Jan (LHO) | O38: Monnier Murielle (LEC) | P38: Kreis Andreas (LLI) | Q38: =IF(AND(K38<>"",K38<Cockpit!$H$6,H38<>"Abgeschlossen"),1,0) -> 0 | R38: 0 | S38: =IF(AND(OR(Cockpit!$B$6="(Alle)",D38=Cockpit!$B$6),OR(Cockpit!$C$6="(Alle)",E38=Cockpit!$C$6),OR(Cockpit!$D$6="(Alle)",F38=Cockpit!$D$6),OR(Cockpit!$E$6="(Alle)",G38=Cockpit!$E$6),OR(Cockpit!$F$6="(Alle)",H38=Cockpit!$F$6),OR(Cockpit!$G$6="(Alle)",O38=Cockpit!$G$6)),1,0) -> 1 | T38: =IF(S38=1,SUM($S$2:S38),"") -> 37
A39: 38 | B39: Define cost allocation principles | C39: Manage and control IT financials › Model and allocate IT costs › Define cost allocation principles | D39: MP | E39: IT planning and steering | F39: Manage and control IT financials | G39: L3 | H39: In Arbeit | I39: 0.5 | J39: 45945 | M39: Ohne Angabe | N39: Frank Nicole (LIS) | O39: Moser Mario (LIS-LAH) | P39: Hynek Tobias (LIS), Kreis Andreas (LLI) | Q39: =IF(AND(K39<>"",K39<Cockpit!$H$6,H39<>"Abgeschlossen"),1,0) -> 0 | R39: 0 | S39: =IF(AND(OR(Cockpit!$B$6="(Alle)",D39=Cockpit!$B$6),OR(Cockpit!$C$6="(Alle)",E39=Cockpit!$C$6),OR(Cockpit!$D$6="(Alle)",F39=Cockpit!$D$6),OR(Cockpit!$E$6="(Alle)",G39=Cockpit!$E$6),OR(Cockpit!$F$6="(Alle)",H39=Cockpit!$F$6),OR(Cockpit!$G$6="(Alle)",O39=Cockpit!$G$6)),1,0) -> 1 | T39: =IF(S39=1,SUM($S$2:S39),"") -> 38
A40: 39 | B40: Define financial management framework | C40: Manage and control IT financials › Manage finance and accounting › Define financial management framework | D40: MP | E40: IT planning and steering | F40: Manage and control IT financials | G40: L3 | H40: In Arbeit | I40: 0.5 | J40: 45945 | M40: Ohne Angabe | N40: Frank Nicole (LIS) | O40: Moser Mario (LIS-LAH) | P40: Hynek Tobias (LIS), Kreis Andreas (LLI) | Q40: =IF(AND(K40<>"",K40<Cockpit!$H$6,H40<>"Abgeschlossen"),1,0) -> 0 | R40: 0 | S40: =IF(AND(OR(Cockpit!$B$6="(Alle)",D40=Cockpit!$B$6),OR(Cockpit!$C$6="(Alle)",E40=Cockpit!$C$6),OR(Cockpit!$D$6="(Alle)",F40=Cockpit!$D$6),OR(Cockpit!$E$6="(Alle)",G40=Cockpit!$E$6),OR(Cockpit!$F$6="(Alle)",H40=Cockpit!$F$6),OR(Cockpit!$G$6="(Alle)",O40=Cockpit!$G$6)),1,0) -> 1 | T40: =IF(S40=1,SUM($S$2:S40),"") -> 39
A41: 40 | B41: Deploy IT service | C41: Build IT Service › Deploy IT service | D41: CP | E41: ITSM | F41: Build IT Service | G41: L2 | H41: In Arbeit | I41: 0 | J41: 46146 | K41: 46234 | M41: In Arbeit | N41: Dalek Martin (LIS) | O41: Wiehe Alexander (COB) | P41: Kunz Christina (LIS-MHP) | Q41: =IF(AND(K41<>"",K41<Cockpit!$H$6,H41<>"Abgeschlossen"),1,0) -> 1 | R41: 0 | S41: =IF(AND(OR(Cockpit!$B$6="(Alle)",D41=Cockpit!$B$6),OR(Cockpit!$C$6="(Alle)",E41=Cockpit!$C$6),OR(Cockpit!$D$6="(Alle)",F41=Cockpit!$D$6),OR(Cockpit!$E$6="(Alle)",G41=Cockpit!$E$6),OR(Cockpit!$F$6="(Alle)",H41=Cockpit!$F$6),OR(Cockpit!$G$6="(Alle)",O41=Cockpit!$G$6)),1,0) -> 1 | T41: =IF(S41=1,SUM($S$2:S41),"") -> 40
A42: 41 | B42: Design IT service | C42: Build IT Service › Design IT service | D42: CP | E42: ITSM | F42: Build IT Service | G42: L2 | H42: In Arbeit | I42: 0.5 | J42: 46146 | K42: 46234 | M42: In Arbeit | N42: Dalek Martin (LIS) | O42: Wiehe Alexander (COB) | P42: Kunz Christina (LIS-MHP) | Q42: =IF(AND(K42<>"",K42<Cockpit!$H$6,H42<>"Abgeschlossen"),1,0) -> 1 | R42: 0 | S42: =IF(AND(OR(Cockpit!$B$6="(Alle)",D42=Cockpit!$B$6),OR(Cockpit!$C$6="(Alle)",E42=Cockpit!$C$6),OR(Cockpit!$D$6="(Alle)",F42=Cockpit!$D$6),OR(Cockpit!$E$6="(Alle)",G42=Cockpit!$E$6),OR(Cockpit!$F$6="(Alle)",H42=Cockpit!$F$6),OR(Cockpit!$G$6="(Alle)",O42=Cockpit!$G$6)),1,0) -> 1 | T42: =IF(S42=1,SUM($S$2:S42),"") -> 41
A43: 42 | B43: Develop and customise IT service | C43: Build IT Service › Develop and customise IT service | D43: CP | E43: ITSM | F43: Build IT Service | G43: L2 | H43: In Arbeit | I43: 0 | J43: 46146 | K43: 46234 | M43: In Arbeit | N43: Dalek Martin (LIS) | O43: Wiehe Alexander (COB) | P43: Kunz Christina (LIS-MHP) | Q43: =IF(AND(K43<>"",K43<Cockpit!$H$6,H43<>"Abgeschlossen"),1,0) -> 1 | R43: 0 | S43: =IF(AND(OR(Cockpit!$B$6="(Alle)",D43=Cockpit!$B$6),OR(Cockpit!$C$6="(Alle)",E43=Cockpit!$C$6),OR(Cockpit!$D$6="(Alle)",F43=Cockpit!$D$6),OR(Cockpit!$E$6="(Alle)",G43=Cockpit!$E$6),OR(Cockpit!$F$6="(Alle)",H43=Cockpit!$F$6),OR(Cockpit!$G$6="(Alle)",O43=Cockpit!$G$6)),1,0) -> 1 | T43: =IF(S43=1,SUM($S$2:S43),"") -> 42
A44: 43 | B44: Develop preliminary budget plan | C44: Manage and control IT financials › Create and maintain IT budgets › Develop preliminary budget plan | D44: MP | E44: IT planning and steering | F44: Manage and control IT financials | G44: L3 | H44: In Arbeit | I44: 0.5 | J44: 45945 | M44: Ohne Angabe | N44: Frank Nicole (LIS) | O44: Mielenz Thomas (LMT) | P44: Hynek Tobias (LIS), Kreis Andreas (LLI) | Q44: =IF(AND(K44<>"",K44<Cockpit!$H$6,H44<>"Abgeschlossen"),1,0) -> 0 | R44: 0 | S44: =IF(AND(OR(Cockpit!$B$6="(Alle)",D44=Cockpit!$B$6),OR(Cockpit!$C$6="(Alle)",E44=Cockpit!$C$6),OR(Cockpit!$D$6="(Alle)",F44=Cockpit!$D$6),OR(Cockpit!$E$6="(Alle)",G44=Cockpit!$E$6),OR(Cockpit!$F$6="(Alle)",H44=Cockpit!$F$6),OR(Cockpit!$G$6="(Alle)",O44=Cockpit!$G$6)),1,0) -> 1 | T44: =IF(S44=1,SUM($S$2:S44),"") -> 43
A45: 44 | B45: Elaborate to-be process | C45: Manage IT processes and continuous improvement › Perform operational process management › Elaborate to-be process | D45: MP | E45: ITSM | F45: Manage IT processes and continuous improvement | G45: L3 | H45: In Arbeit | I45: 0.25 | J45: 46034 | K45: 46173 | L45: 100 | M45: In Arbeit | N45: Rollinger Alexander (LIS) | O45: Reiner Heiko (HAU-ITSA) | P45: Rollinger Alexander (LIS) | Q45: =IF(AND(K45<>"",K45<Cockpit!$H$6,H45<>"Abgeschlossen"),1,0) -> 1 | R45: 0 | S45: =IF(AND(OR(Cockpit!$B$6="(Alle)",D45=Cockpit!$B$6),OR(Cockpit!$C$6="(Alle)",E45=Cockpit!$C$6),OR(Cockpit!$D$6="(Alle)",F45=Cockpit!$D$6),OR(Cockpit!$E$6="(Alle)",G45=Cockpit!$E$6),OR(Cockpit!$F$6="(Alle)",H45=Cockpit!$F$6),OR(Cockpit!$G$6="(Alle)",O45=Cockpit!$G$6)),1,0) -> 1 | T45: =IF(S45=1,SUM($S$2:S45),"") -> 44
A46: 45 | B46: Ensure Information security | C46: Ensure Information security | D46: SP | E46: Information security | F46: Ensure Information security | G46: L1 | H46: In Arbeit | I46: 0.5 | J46: 45946 | K46: 45946 | L46: 1 | M46: Ohne Angabe | N46: Da Silva Alessandro (LIN) | O46: Monnier Murielle (LEC) | P46: Rollinger Alexander (LIS) | Q46: =IF(AND(K46<>"",K46<Cockpit!$H$6,H46<>"Abgeschlossen"),1,0) -> 1 | R46: 0 | S46: =IF(AND(OR(Cockpit!$B$6="(Alle)",D46=Cockpit!$B$6),OR(Cockpit!$C$6="(Alle)",E46=Cockpit!$C$6),OR(Cockpit!$D$6="(Alle)",F46=Cockpit!$D$6),OR(Cockpit!$E$6="(Alle)",G46=Cockpit!$E$6),OR(Cockpit!$F$6="(Alle)",H46=Cockpit!$F$6),OR(Cockpit!$G$6="(Alle)",O46=Cockpit!$G$6)),1,0) -> 1 | T46: =IF(S46=1,SUM($S$2:S46),"") -> 45
A47: 46 | B47: Establish cost allocation model | C47: Manage and control IT financials › Model and allocate IT costs › Establish cost allocation model | D47: MP | E47: IT planning and steering | F47: Manage and control IT financials | G47: L3 | H47: In Arbeit | I47: 0.5 | J47: 45945 | M47: Ohne Angabe | N47: Frank Nicole (LIS) | O47: Moser Mario (LIS-LAH) | P47: Hynek Tobias (LIS), Kreis Andreas (LLI) | Q47: =IF(AND(K47<>"",K47<Cockpit!$H$6,H47<>"Abgeschlossen"),1,0) -> 0 | R47: 0 | S47: =IF(AND(OR(Cockpit!$B$6="(Alle)",D47=Cockpit!$B$6),OR(Cockpit!$C$6="(Alle)",E47=Cockpit!$C$6),OR(Cockpit!$D$6="(Alle)",F47=Cockpit!$D$6),OR(Cockpit!$E$6="(Alle)",G47=Cockpit!$E$6),OR(Cockpit!$F$6="(Alle)",H47=Cockpit!$F$6),OR(Cockpit!$G$6="(Alle)",O47=Cockpit!$G$6)),1,0) -> 1 | T47: =IF(S47=1,SUM($S$2:S47),"") -> 46
A48: 47 | B48: Establish financial accounting structure | C48: Manage and control IT financials › Manage finance and accounting › Establish financial accounting structure | D48: MP | E48: IT planning and steering | F48: Manage and control IT financials | G48: L3 | H48: In Arbeit | I48: 0.5 | J48: 45945 | M48: Ohne Angabe | N48: Frank Nicole (LIS) | O48: Moser Mario (LIS-LAH) | P48: Hynek Tobias (LIS), Kreis Andreas (LLI) | Q48: =IF(AND(K48<>"",K48<Cockpit!$H$6,H48<>"Abgeschlossen"),1,0) -> 0 | R48: 0 | S48: =IF(AND(OR(Cockpit!$B$6="(Alle)",D48=Cockpit!$B$6),OR(Cockpit!$C$6="(Alle)",E48=Cockpit!$C$6),OR(Cockpit!$D$6="(Alle)",F48=Cockpit!$D$6),OR(Cockpit!$E$6="(Alle)",G48=Cockpit!$E$6),OR(Cockpit!$F$6="(Alle)",H48=Cockpit!$F$6),OR(Cockpit!$G$6="(Alle)",O48=Cockpit!$G$6)),1,0) -> 1 | T48: =IF(S48=1,SUM($S$2:S48),"") -> 47
A49: 48 | B49: Evaluate success of IT service rollout | C49: Build IT Service › Evaluate success of IT service rollout | D49: CP | E49: ITSM | F49: Build IT Service | G49: L2 | H49: In Arbeit | I49: 0 | J49: 46146 | K49: 46234 | M49: In Arbeit | N49: Dalek Martin (LIS) | O49: Wiehe Alexander (COB) | P49: Kunz Christina (LIS-MHP) | Q49: =IF(AND(K49<>"",K49<Cockpit!$H$6,H49<>"Abgeschlossen"),1,0) -> 1 | R49: 0 | S49: =IF(AND(OR(Cockpit!$B$6="(Alle)",D49=Cockpit!$B$6),OR(Cockpit!$C$6="(Alle)",E49=Cockpit!$C$6),OR(Cockpit!$D$6="(Alle)",F49=Cockpit!$D$6),OR(Cockpit!$E$6="(Alle)",G49=Cockpit!$E$6),OR(Cockpit!$F$6="(Alle)",H49=Cockpit!$F$6),OR(Cockpit!$G$6="(Alle)",O49=Cockpit!$G$6)),1,0) -> 1 | T49: =IF(S49=1,SUM($S$2:S49),"") -> 48
A50: 49 | B50: Gather relevant cost and consumption data | C50: Manage and control IT financials › Model and allocate IT costs › Gather relevant cost and consumption data | D50: MP | E50: IT planning and steering | F50: Manage and control IT financials | G50: L3 | H50: In Arbeit | I50: 0.5 | J50: 45945 | M50: Ohne Angabe | N50: Frank Nicole (LIS) | O50: Moser Mario (LIS-LAH) | P50: Hynek Tobias (LIS), Kreis Andreas (LLI) | Q50: =IF(AND(K50<>"",K50<Cockpit!$H$6,H50<>"Abgeschlossen"),1,0) -> 0 | R50: 0 | S50: =IF(AND(OR(Cockpit!$B$6="(Alle)",D50=Cockpit!$B$6),OR(Cockpit!$C$6="(Alle)",E50=Cockpit!$C$6),OR(Cockpit!$D$6="(Alle)",F50=Cockpit!$D$6),OR(Cockpit!$E$6="(Alle)",G50=Cockpit!$E$6),OR(Cockpit!$F$6="(Alle)",H50=Cockpit!$F$6),OR(Cockpit!$G$6="(Alle)",O50=Cockpit!$G$6)),1,0) -> 1 | T50: =IF(S50=1,SUM($S$2:S50),"") -> 49
...

Sheet Phasen
A1: Nr | B1: Prozess | C1: Gruppe | D1: Phase | E1: Status | F1: Start | G1: Ende | H1: Dauer (T) | I1: Treffer
A2: 1 | B2: Analyse architecture impact | C2: CP | D2: Elaboration | E2: Abgeschlossen | F2: 45870 | G2: 45945 | H2: 54 | I2: =INDEX(Prozesse!$S$2:$S$125,MATCH(A2,Prozesse!$A$2:$A$125,0)) -> 1
A3: 1 | B3: Analyse architecture impact | C3: CP | D3: Implementation LIS | E3: Ohne Angabe | F3: 46327 | G3: 46081 | H3: 0 | I3: =INDEX(Prozesse!$S$2:$S$125,MATCH(A3,Prozesse!$A$2:$A$125,0)) -> 1
A4: 1 | B4: Analyse architecture impact | C4: CP | D4: Implementation LUS | E4: Ohne Angabe | I4: =INDEX(Prozesse!$S$2:$S$125,MATCH(A4,Prozesse!$A$2:$A$125,0)) -> 1
A5: 1 | B5: Analyse architecture impact | C5: CP | D5: Implementation COT | E5: Verzögert | F5: 45946 | G5: 46142 | H5: 141 | I5: =INDEX(Prozesse!$S$2:$S$125,MATCH(A5,Prozesse!$A$2:$A$125,0)) -> 1
A6: 2 | B6: Approve IT demand | C6: CP | D6: Elaboration | E6: Abgeschlossen | F6: 45870 | G6: 45870 | H6: 1 | I6: =INDEX(Prozesse!$S$2:$S$125,MATCH(A6,Prozesse!$A$2:$A$125,0)) -> 1
A7: 2 | B7: Approve IT demand | C7: CP | D7: Implementation LIS | E7: Verzögert | F7: 45962 | G7: 46081 | H7: 85 | I7: =INDEX(Prozesse!$S$2:$S$125,MATCH(A7,Prozesse!$A$2:$A$125,0)) -> 1
A8: 2 | B8: Approve IT demand | C8: CP | D8: Implementation LUS | E8: Ohne Angabe | I8: =INDEX(Prozesse!$S$2:$S$125,MATCH(A8,Prozesse!$A$2:$A$125,0)) -> 1
A9: 2 | B9: Approve IT demand | C9: CP | D9: Implementation COT | E9: Verzögert | F9: 45964 | G9: 46112 | H9: 107 | I9: =INDEX(Prozesse!$S$2:$S$125,MATCH(A9,Prozesse!$A$2:$A$125,0)) -> 1
A10: 3 | B10: Attract and hire employees | C10: SP | D10: Elaboration | E10: In Arbeit | F10: 46029 | G10: 46097 | H10: 49 | I10: =INDEX(Prozesse!$S$2:$S$125,MATCH(A10,Prozesse!$A$2:$A$125,0)) -> 1
A11: 3 | B11: Attract and hire employees | C11: SP | D11: Implementation LIS | E11: Verzögert | F11: 46113 | G11: 46188 | H11: 54 | I11: =INDEX(Prozesse!$S$2:$S$125,MATCH(A11,Prozesse!$A$2:$A$125,0)) -> 1
A12: 3 | B12: Attract and hire employees | C12: SP | D12: Implementation LUS | E12: Ohne Angabe | I12: =INDEX(Prozesse!$S$2:$S$125,MATCH(A12,Prozesse!$A$2:$A$125,0)) -> 1
A13: 3 | B13: Attract and hire employees | C13: SP | D13: Implementation COT | E13: Verzögert | F13: 46113 | G13: 46188 | H13: 54 | I13: =INDEX(Prozesse!$S$2:$S$125,MATCH(A13,Prozesse!$A$2:$A$125,0)) -> 1
A14: 4 | B14: Define solution target architecture | C14: CP | D14: Elaboration | E14: In Arbeit | F14: 46058 | G14: 46188 | H14: 54 | I14: =INDEX(Prozesse!$S$2:$S$125,MATCH(A14,Prozesse!$A$2:$A$125,0)) -> 1
A15: 4 | B15: Define solution target architecture | C15: CP | D15: Implementation LIS | E15: Verzögert | I15: =INDEX(Prozesse!$S$2:$S$125,MATCH(A15,Prozesse!$A$2:$A$125,0)) -> 1
A16: 4 | B16: Define solution target architecture | C16: CP | D16: Implementation LUS | E16: Verzögert | I16: =INDEX(Prozesse!$S$2:$S$125,MATCH(A16,Prozesse!$A$2:$A$125,0)) -> 1
A17: 4 | B17: Define solution target architecture | C17: CP | D17: Implementation COT | E17: Verzögert | I17: =INDEX(Prozesse!$S$2:$S$125,MATCH(A17,Prozesse!$A$2:$A$125,0)) -> 1
A18: 5 | B18: Ensure performance and conformance of IT services | C18: SP | D18: Elaboration | E18: Verzögert | I18: =INDEX(Prozesse!$S$2:$S$125,MATCH(A18,Prozesse!$A$2:$A$125,0)) -> 1
A19: 5 | B19: Ensure performance and conformance of IT services | C19: SP | D19: Implementation LIS | E19: Ohne Angabe | I19: =INDEX(Prozesse!$S$2:$S$125,MATCH(A19,Prozesse!$A$2:$A$125,0)) -> 1
A20: 5 | B20: Ensure performance and conformance of IT services | C20: SP | D20: Implementation LUS | E20: Ohne Angabe | I20: =INDEX(Prozesse!$S$2:$S$125,MATCH(A20,Prozesse!$A$2:$A$125,0)) -> 1
A21: 5 | B21: Ensure performance and conformance of IT services | C21: SP | D21: Implementation COT | E21: Ohne Angabe | I21: =INDEX(Prozesse!$S$2:$S$125,MATCH(A21,Prozesse!$A$2:$A$125,0)) -> 1
A22: 6 | B22: Evaluate and qualify IT demand | C22: CP | D22: Elaboration | E22: Abgeschlossen | F22: 45870 | G22: 45870 | H22: 1 | I22: =INDEX(Prozesse!$S$2:$S$125,MATCH(A22,Prozesse!$A$2:$A$125,0)) -> 1
A23: 6 | B23: Evaluate and qualify IT demand | C23: CP | D23: Implementation LIS | E23: Verzögert | F23: 45962 | G23: 46081 | H23: 85 | I23: =INDEX(Prozesse!$S$2:$S$125,MATCH(A23,Prozesse!$A$2:$A$125,0)) -> 1
A24: 6 | B24: Evaluate and qualify IT demand | C24: CP | D24: Implementation LUS | E24: Ohne Angabe | I24: =INDEX(Prozesse!$S$2:$S$125,MATCH(A24,Prozesse!$A$2:$A$125,0)) -> 1
A25: 6 | B25: Evaluate and qualify IT demand | C25: CP | D25: Implementation COT | E25: Verzögert | F25: 45964 | G25: 46112 | H25: 107 | I25: =INDEX(Prozesse!$S$2:$S$125,MATCH(A25,Prozesse!$A$2:$A$125,0)) -> 1
A26: 7 | B26: Handle IT service order | C26: CP | D26: Elaboration | E26: Verzögert | F26: 46113 | G26: 46190 | H26: 56 | I26: =INDEX(Prozesse!$S$2:$S$125,MATCH(A26,Prozesse!$A$2:$A$125,0)) -> 1
A27: 7 | B27: Handle IT service order | C27: CP | D27: Implementation LIS | E27: Verzögert | F27: 46113 | G27: 46188 | H27: 54 | I27: =INDEX(Prozesse!$S$2:$S$125,MATCH(A27,Prozesse!$A$2:$A$125,0)) -> 1
A28: 7 | B28: Handle IT service order | C28: CP | D28: Implementation LUS | E28: Ohne Angabe | I28: =INDEX(Prozesse!$S$2:$S$125,MATCH(A28,Prozesse!$A$2:$A$125,0)) -> 1
A29: 7 | B29: Handle IT service order | C29: CP | D29: Implementation COT | E29: Ohne Angabe | I29: =INDEX(Prozesse!$S$2:$S$125,MATCH(A29,Prozesse!$A$2:$A$125,0)) -> 1
A30: 8 | B30: Implement and maintain IT job architecture | C30: SP | D30: Elaboration | E30: Verzögert | F30: 45946 | G30: 46173 | H30: 162 | I30: =INDEX(Prozesse!$S$2:$S$125,MATCH(A30,Prozesse!$A$2:$A$125,0)) -> 1
A31: 8 | B31: Implement and maintain IT job architecture | C31: SP | D31: Implementation LIS | E31: Ohne Angabe | I31: =INDEX(Prozesse!$S$2:$S$125,MATCH(A31,Prozesse!$A$2:$A$125,0)) -> 1
A32: 8 | B32: Implement and maintain IT job architecture | C32: SP | D32: Implementation LUS | E32: Ohne Angabe | I32: =INDEX(Prozesse!$S$2:$S$125,MATCH(A32,Prozesse!$A$2:$A$125,0)) -> 1
A33: 8 | B33: Implement and maintain IT job architecture | C33: SP | D33: Implementation COT | E33: Ohne Angabe | I33: =INDEX(Prozesse!$S$2:$S$125,MATCH(A33,Prozesse!$A$2:$A$125,0)) -> 1
A34: 9 | B34: Maintain IT glossary | C34: MP | D34: Elaboration | E34: Ohne Angabe | F34: 46029 | I34: =INDEX(Prozesse!$S$2:$S$125,MATCH(A34,Prozesse!$A$2:$A$125,0)) -> 1
A35: 9 | B35: Maintain IT glossary | C35: MP | D35: Implementation LIS | E35: Verzögert | F35: 46029 | G35: 46039 | H35: 7 | I35: =INDEX(Prozesse!$S$2:$S$125,MATCH(A35,Prozesse!$A$2:$A$125,0)) -> 1
A36: 9 | B36: Maintain IT glossary | C36: MP | D36: Implementation LUS | E36: Ohne Angabe | I36: =INDEX(Prozesse!$S$2:$S$125,MATCH(A36,Prozesse!$A$2:$A$125,0)) -> 1
A37: 9 | B37: Maintain IT glossary | C37: MP | D37: Implementation COT | E37: Ohne Angabe | F37: 46029 | I37: =INDEX(Prozesse!$S$2:$S$125,MATCH(A37,Prozesse!$A$2:$A$125,0)) -> 1
A38: 10 | B38: Manage HR4IT service demand | C38: SP | D38: Elaboration | E38: Verzögert | F38: 45931 | G38: 46173 | H38: 173 | I38: =INDEX(Prozesse!$S$2:$S$125,MATCH(A38,Prozesse!$A$2:$A$125,0)) -> 1
A39: 10 | B39: Manage HR4IT service demand | C39: SP | D39: Implementation LIS | E39: Terminiert | F39: 46174 | G39: 46203 | H39: 22 | I39: =INDEX(Prozesse!$S$2:$S$125,MATCH(A39,Prozesse!$A$2:$A$125,0)) -> 1
A40: 10 | B40: Manage HR4IT service demand | C40: SP | D40: Implementation LUS | E40: Terminiert | F40: 46174 | G40: 46203 | H40: 22 | I40: =INDEX(Prozesse!$S$2:$S$125,MATCH(A40,Prozesse!$A$2:$A$125,0)) -> 1
...

Sheet Listen
A1: Auswahllisten für die Felder im Cockpit
A2: Prozessgruppe | B2: Initiative | C2: L1-Prozess | D2: Ebene | E2: Status | F2: Process Manager
A3: (Alle) | B3: (Alle) | C3: (Alle) | D3: (Alle) | E3: (Alle) | F3: (Alle)
A4: CP | B4: Architecture management | C4: Build IT Service | D4: L1 | E4: Verzögert | F4: Mielenz Thomas (LMT)
A5: MP | B5: Central area (Jan Müskens) | C5: Deliver IT service | D5: L2 | E5: In Arbeit | F5: Monnier Murielle (LEC)
A6: SP | B6: Corporate IT body | C6: Ensure Information security | D6: L3 | E6: Terminiert | F6: Moser Mario (LIS-LAH)
B7: HR initiatives for IT | C7: Ensure performance and conformance of IT services | D7: L4 | E7: Abgeschlossen | F7: Nussbaumer Florian (LBC)
B8: IT planning and steering | C8: Leverage IT innovation | E8: Nicht geplant | F8: Reiner Heiko (HAU-ITSA)
B9: IT project management | C9: Manage IT governance framework | F9: Rollinger Alexander (LIS)
B10: ITSM | C10: Manage IT knowledge | F10: Schnurrenberger Christoph (LIS-LIN)
B11: Information security | C11: Manage IT portfolio | F11: Sint Rachel (LBH)
B12: n/a | C12: Manage IT processes and continuous improvement | F12: Wiehe Alexander (COB)
C13: Manage IT project | F13: –
C14: Manage IT risks and compliance
C15: Manage IT sourcing and procurement
C16: Manage IT stakeholder relationships
C17: Manage IT strategy
C18: Manage and control IT financials
C19: Manage enterprise architecture
C20: Plan IT service
C21: Provide and develop IT workforce
C22: Run IT service

Sheet Auswertung
A1: Auswertung – speist die Diagramme im Cockpit. Alle Werte sind Formeln über die Trefferspalte.
A3: Status | B3: Anzahl | D3: Prozessgruppe | E3: Verzögert | F3: In Arbeit | G3: Terminiert | H3: Abgeschlossen | I3: Nicht geplant
A4: Verzögert | B4: =SUMPRODUCT(Prozesse!$S$2:$S$125,--(Prozesse!$H$2:$H$125=$A4)) -> 29 | C4: MP | D4: MP · Management | E4: =SUMPRODUCT(Prozesse!$S$2:$S$125,--(Prozesse!$D$2:$D$125=$C4),--(Prozesse!$H$2:$H$125=E$3)) -> 6 | F4: =SUMPRODUCT(Prozesse!$S$2:$S$125,--(Prozesse!$D$2:$D$125=$C4),--(Prozesse!$H$2:$H$125=F$3)) -> 39 | G4: =SUMPRODUCT(Prozesse!$S$2:$S$125,--(Prozesse!$D$2:$D$125=$C4),--(Prozesse!$H$2:$H$125=G$3)) -> 1 | H4: =SUMPRODUCT(Prozesse!$S$2:$S$125,--(Prozesse!$D$2:$D$125=$C4),--(Prozesse!$H$2:$H$125=H$3)) -> 3 | I4: =SUMPRODUCT(Prozesse!$S$2:$S$125,--(Prozesse!$D$2:$D$125=$C4),--(Prozesse!$H$2:$H$125=I$3)) -> 2
A5: In Arbeit | B5: =SUMPRODUCT(Prozesse!$S$2:$S$125,--(Prozesse!$H$2:$H$125=$A5)) -> 59 | C5: CP | D5: CP · Core | E5: =SUMPRODUCT(Prozesse!$S$2:$S$125,--(Prozesse!$D$2:$D$125=$C5),--(Prozesse!$H$2:$H$125=E$3)) -> 12 | F5: =SUMPRODUCT(Prozesse!$S$2:$S$125,--(Prozesse!$D$2:$D$125=$C5),--(Prozesse!$H$2:$H$125=F$3)) -> 10 | G5: =SUMPRODUCT(Prozesse!$S$2:$S$125,--(Prozesse!$D$2:$D$125=$C5),--(Prozesse!$H$2:$H$125=G$3)) -> 3 | H5: =SUMPRODUCT(Prozesse!$S$2:$S$125,--(Prozesse!$D$2:$D$125=$C5),--(Prozesse!$H$2:$H$125=H$3)) -> 7 | I5: =SUMPRODUCT(Prozesse!$S$2:$S$125,--(Prozesse!$D$2:$D$125=$C5),--(Prozesse!$H$2:$H$125=I$3)) -> 10
A6: Terminiert | B6: =SUMPRODUCT(Prozesse!$S$2:$S$125,--(Prozesse!$H$2:$H$125=$A6)) -> 7 | C6: SP | D6: SP · Support | E6: =SUMPRODUCT(Prozesse!$S$2:$S$125,--(Prozesse!$D$2:$D$125=$C6),--(Prozesse!$H$2:$H$125=E$3)) -> 11 | F6: =SUMPRODUCT(Prozesse!$S$2:$S$125,--(Prozesse!$D$2:$D$125=$C6),--(Prozesse!$H$2:$H$125=F$3)) -> 10 | G6: =SUMPRODUCT(Prozesse!$S$2:$S$125,--(Prozesse!$D$2:$D$125=$C6),--(Prozesse!$H$2:$H$125=G$3)) -> 3 | H6: =SUMPRODUCT(Prozesse!$S$2:$S$125,--(Prozesse!$D$2:$D$125=$C6),--(Prozesse!$H$2:$H$125=H$3)) -> 7 | I6: =SUMPRODUCT(Prozesse!$S$2:$S$125,--(Prozesse!$D$2:$D$125=$C6),--(Prozesse!$H$2:$H$125=I$3)) -> 0
A7: Abgeschlossen | B7: =SUMPRODUCT(Prozesse!$S$2:$S$125,--(Prozesse!$H$2:$H$125=$A7)) -> 17
A8: Nicht geplant | B8: =SUMPRODUCT(Prozesse!$S$2:$S$125,--(Prozesse!$H$2:$H$125=$A8)) -> 12
A10: Initiative | B10: Ø Fortschritt | C10: Prozesse | E10: L1-Prozessbereich | F10: davon verzögert
A11: Architecture management | B11: =IFERROR(SUMPRODUCT(Prozesse!$S$2:$S$125,--(Prozesse!$E$2:$E$125=$A11),Prozesse!$I$2:$I$125)/SUMPRODUCT(Prozesse!$S$2:$S$125,--(Prozesse!$E$2:$E$125=$A11)),0) -> 0.92857143 | C11: =SUMPRODUCT(Prozesse!$S$2:$S$125,--(Prozesse!$E$2:$E$125=$A11)) -> 7 | E11: Provide and develop IT workforce | F11: =SUMPRODUCT(Prozesse!$S$2:$S$125,--(Prozesse!$F$2:$F$125=$E11),--(Prozesse!$H$2:$H$125="Verzögert")) -> 9
A12: Central area (Jan Müskens) | B12: =IFERROR(SUMPRODUCT(Prozesse!$S$2:$S$125,--(Prozesse!$E$2:$E$125=$A12),Prozesse!$I$2:$I$125)/SUMPRODUCT(Prozesse!$S$2:$S$125,--(Prozesse!$E$2:$E$125=$A12)),0) -> 0.21875 | C12: =SUMPRODUCT(Prozesse!$S$2:$S$125,--(Prozesse!$E$2:$E$125=$A12)) -> 8 | E12: Plan IT service | F12: =SUMPRODUCT(Prozesse!$S$2:$S$125,--(Prozesse!$F$2:$F$125=$E12),--(Prozesse!$H$2:$H$125="Verzögert")) -> 5
A13: Corporate IT body | B13: =IFERROR(SUMPRODUCT(Prozesse!$S$2:$S$125,--(Prozesse!$E$2:$E$125=$A13),Prozesse!$I$2:$I$125)/SUMPRODUCT(Prozesse!$S$2:$S$125,--(Prozesse!$E$2:$E$125=$A13)),0) -> 0.56818182 | C13: =SUMPRODUCT(Prozesse!$S$2:$S$125,--(Prozesse!$E$2:$E$125=$A13)) -> 11 | E13: Run IT service | F13: =SUMPRODUCT(Prozesse!$S$2:$S$125,--(Prozesse!$F$2:$F$125=$E13),--(Prozesse!$H$2:$H$125="Verzögert")) -> 3
A14: HR initiatives for IT | B14: =IFERROR(SUMPRODUCT(Prozesse!$S$2:$S$125,--(Prozesse!$E$2:$E$125=$A14),Prozesse!$I$2:$I$125)/SUMPRODUCT(Prozesse!$S$2:$S$125,--(Prozesse!$E$2:$E$125=$A14)),0) -> 0.12611111 | C14: =SUMPRODUCT(Prozesse!$S$2:$S$125,--(Prozesse!$E$2:$E$125=$A14)) -> 18 | E14: Deliver IT service | F14: =SUMPRODUCT(Prozesse!$S$2:$S$125,--(Prozesse!$F$2:$F$125=$E14),--(Prozesse!$H$2:$H$125="Verzögert")) -> 2
A15: IT planning and steering | B15: =IFERROR(SUMPRODUCT(Prozesse!$S$2:$S$125,--(Prozesse!$E$2:$E$125=$A15),Prozesse!$I$2:$I$125)/SUMPRODUCT(Prozesse!$S$2:$S$125,--(Prozesse!$E$2:$E$125=$A15)),0) -> 0.5 | C15: =SUMPRODUCT(Prozesse!$S$2:$S$125,--(Prozesse!$E$2:$E$125=$A15)) -> 21 | E15: Build IT Service | F15: =SUMPRODUCT(Prozesse!$S$2:$S$125,--(Prozesse!$F$2:$F$125=$E15),--(Prozesse!$H$2:$H$125="Verzögert")) -> 2
A16: IT project management | B16: =IFERROR(SUMPRODUCT(Prozesse!$S$2:$S$125,--(Prozesse!$E$2:$E$125=$A16),Prozesse!$I$2:$I$125)/SUMPRODUCT(Prozesse!$S$2:$S$125,--(Prozesse!$E$2:$E$125=$A16)),0) -> 1 | C16: =SUMPRODUCT(Prozesse!$S$2:$S$125,--(Prozesse!$E$2:$E$125=$A16)) -> 8 | E16: Manage enterprise architecture | F16: =SUMPRODUCT(Prozesse!$S$2:$S$125,--(Prozesse!$F$2:$F$125=$E16),--(Prozesse!$H$2:$H$125="Verzögert")) -> 2
A17: ITSM | B17: =IFERROR(SUMPRODUCT(Prozesse!$S$2:$S$125,--(Prozesse!$E$2:$E$125=$A17),Prozesse!$I$2:$I$125)/SUMPRODUCT(Prozesse!$S$2:$S$125,--(Prozesse!$E$2:$E$125=$A17)),0) -> 0.28333333 | C17: =SUMPRODUCT(Prozesse!$S$2:$S$125,--(Prozesse!$E$2:$E$125=$A17)) -> 48 | E17: Ensure performance and conformance of IT services | F17: =SUMPRODUCT(Prozesse!$S$2:$S$125,--(Prozesse!$F$2:$F$125=$E17),--(Prozesse!$H$2:$H$125="Verzögert")) -> 1
A18: Information security | B18: =IFERROR(SUMPRODUCT(Prozesse!$S$2:$S$125,--(Prozesse!$E$2:$E$125=$A18),Prozesse!$I$2:$I$125)/SUMPRODUCT(Prozesse!$S$2:$S$125,--(Prozesse!$E$2:$E$125=$A18)),0) -> 0.5 | C18: =SUMPRODUCT(Prozesse!$S$2:$S$125,--(Prozesse!$E$2:$E$125=$A18)) -> 2 | E18: Manage IT processes and continuous improvement | F18: =SUMPRODUCT(Prozesse!$S$2:$S$125,--(Prozesse!$F$2:$F$125=$E18),--(Prozesse!$H$2:$H$125="Verzögert")) -> 1
A19: n/a | B19: =IFERROR(SUMPRODUCT(Prozesse!$S$2:$S$125,--(Prozesse!$E$2:$E$125=$A19),Prozesse!$I$2:$I$125)/SUMPRODUCT(Prozesse!$S$2:$S$125,--(Prozesse!$E$2:$E$125=$A19)),0) -> 0.22 | C19: =SUMPRODUCT(Prozesse!$S$2:$S$125,--(Prozesse!$E$2:$E$125=$A19)) -> 1 | E19: Manage IT knowledge | F19: =SUMPRODUCT(Prozesse!$S$2:$S$125,--(Prozesse!$F$2:$F$125=$E19),--(Prozesse!$H$2:$H$125="Verzögert")) -> 1
E20: Manage IT portfolio | F20: =SUMPRODUCT(Prozesse!$S$2:$S$125,--(Prozesse!$F$2:$F$125=$E20),--(Prozesse!$H$2:$H$125="Verzögert")) -> 1
A23: Phase | B23: terminiert | C23: abgeschlossen
A24: Elaboration | B24: =SUMPRODUCT(Phasen!$I$2:$I$497,--(Phasen!$D$2:$D$497=$A24),--(Phasen!$F$2:$F$497<>"")) -> 104 | C24: =SUMPRODUCT(Phasen!$I$2:$I$497,--(Phasen!$D$2:$D$497=$A24),--(Phasen!$E$2:$E$497="Abgeschlossen")) -> 30
A25: Implementation LIS | B25: =SUMPRODUCT(Phasen!$I$2:$I$497,--(Phasen!$D$2:$D$497=$A25),--(Phasen!$F$2:$F$497<>"")) -> 30 | C25: =SUMPRODUCT(Phasen!$I$2:$I$497,--(Phasen!$D$2:$D$497=$A25),--(Phasen!$E$2:$E$497="Abgeschlossen")) -> 0
A26: Implementation LUS | B26: =SUMPRODUCT(Phasen!$I$2:$I$497,--(Phasen!$D$2:$D$497=$A26),--(Phasen!$F$2:$F$497<>"")) -> 4 | C26: =SUMPRODUCT(Phasen!$I$2:$I$497,--(Phasen!$D$2:$D$497=$A26),--(Phasen!$E$2:$E$497="Abgeschlossen")) -> 0
A27: Implementation COT | B27: =SUMPRODUCT(Phasen!$I$2:$I$497,--(Phasen!$D$2:$D$497=$A27),--(Phasen!$F$2:$F$497<>"")) -> 12 | C27: =SUMPRODUCT(Phasen!$I$2:$I$497,--(Phasen!$D$2:$D$497=$A27),--(Phasen!$E$2:$E$497="Abgeschlossen")) -> 0

Sheet Hinweise
B2: IT Process Portfolio – Cockpit
B4: Bedienung
B5: Im Blatt Cockpit die gelb hinterlegten Auswahlfelder ändern. Kennzahlen, Diagramme und
B6: die Trefferliste rechnen sofort neu. Alle übrigen Zellen sind gesperrt, damit nichts
B7: versehentlich überschrieben wird; ein Kennwort wird dafür nicht benötigt.
B8: Die Blätter Prozesse und Phasen tragen echte Excel-Tabellen: dort lässt sich zusätzlich
B9: über die Spaltenköpfe filtern und sortieren.
B11: Gemeinsames Arbeiten
B12: Die Auswahlfelder sind Zellen der Mappe. Ändert sie jemand, sehen alle anderen dieselbe
B13: Auswahl. Wer für sich allein filtern möchte, nutzt in Excel für das Web auf den Blättern
B14: Prozesse oder Phasen die Blattansicht (Ansicht > Blattansicht > Neu).
B16: Wie der Status entsteht
... B34: Neu erzeugen nach einer aktualisierten Planung: python3 build/excel.py
