Workbook
Name Task_Table1: Task_Table1!$A$1:$P$1

Sheet Task_Table1
A1: Initative | B1: Process | C1: Phase | D1: Process level | E1: Process group | F1: Percent complete | G1: IT process Consultant | H1: Responsible | I1: Care taker | J1: Start | K1: End | L1: Duration | M1: Approval date | N1: Actual phase | O1: Planned phase | P1: Associated process on L1
A2: Corporate IT body | B2: Manage IT strategy | C2: Total | D2: L1 | E2: MP | F2: 0.07 | J2: 46029 | K2: 46203 | L2: =NETWORKDAYS(J2,K2) -> 125 | O2: 1 | P2: Manage IT strategy
A3: Corporate IT body | B3: Manage IT strategy | C3: Elaboration | D3: L1 | E3: MP | F3: 0.15 | G3: Kunz Christina (LIS-MHP Management- und IT Beratung GmbH) | H3: Felder Max (LLI) | I3: Mielenz Thomas (LMT) | J3: 46029 | K3: 46097 | L3: =NETWORKDAYS(J3,K3) -> 49 | N3: Elaboration in progress | O3: Scheduled | P3: Manage IT strategy
A4: Corporate IT body | B4: Manage IT strategy | C4: Implementation LIS | D4: L1 | E4: MP | F4: 0 | J4: 46127 | K4: 46203 | L4: =NETWORKDAYS(J4,K4) -> 55 | O4: Scheduled | P4: Manage IT strategy
A5: Corporate IT body | B5: Manage IT strategy | C5: Implementation COT | D5: L1 | E5: MP | F5: 0 | L5: =NETWORKDAYS(J5,K5) -> 0 | P5: Manage IT strategy
A6: Corporate IT body | B6: Manage IT strategy | C6: Implementation LUS | D6: L1 | E6: MP | F6: 0 | L6: =NETWORKDAYS(J6,K6) -> 0 | P6: Manage IT strategy
A7: Corporate IT body | B7: Manage IT governance framework | C7: Total | D7: L1 | E7: MP | F7: 0 | J7: 46029 | K7: 46203 | L7: =NETWORKDAYS(J7,K7) -> 125 | P7: Manage IT governance framework
A8: Corporate IT body | B8: Manage IT governance framework | C8: Elaboration | D8: L1 | E8: MP | F8: 0 | G8: Kunz Christina (LIS-MHP Management- und IT Beratung GmbH) | H8: Felder Max (LLI) | I8: Mielenz Thomas (LMT) | J8: 46029 | K8: 46097 | L8: =NETWORKDAYS(J8,K8) -> 49 | O8: Scheduled | P8: Manage IT governance framework
A9: Corporate IT body | B9: Manage IT governance framework | C9: Implementation LIS | D9: L1 | E9: MP | F9: 0 | J9: 46127 | K9: 46203 | L9: =NETWORKDAYS(J9,K9) -> 55 | O9: Scheduled | P9: Manage IT governance framework
A10: Corporate IT body | B10: Manage IT governance framework | C10: Implementation COT | D10: L1 | E10: MP | F10: 0 | L10: =NETWORKDAYS(J10,K10) -> 0 | P10: Manage IT governance framework
A11: Corporate IT body | B11: Manage IT governance framework | C11: Implementation LUS | D11: L1 | E11: MP | F11: 0 | L11: =NETWORKDAYS(J11,K11) -> 0 | P11: Manage IT governance framework
A12: Corporate IT body | B12: Maintain IT glossary | C12: Total | D12: L2 | E12: MP | F12: 0 | L12: =NETWORKDAYS(J12,K12) -> 0 | P12: Manage IT governance framework
A13: Corporate IT body | B13: Maintain IT glossary | C13: Elaboration | D13: L2 | E13: MP | F13: 0 | G13: Kunz Christina (LIS-MHP Management- und IT Beratung GmbH) | H13: Felder Max (LLI) | I13: Mielenz Thomas (LMT) | L13: =NETWORKDAYS(J13,K13) -> 0 | P13: Manage IT governance framework
A14: Corporate IT body | B14: Maintain IT glossary | C14: Implementation LIS | D14: L2 | E14: MP | F14: 0 | J14: 46029 | K14: 46039 | L14: =NETWORKDAYS(J14,K14) -> 8 | O14: Scheduled | P14: Manage IT governance framework
A15: Corporate IT body | B15: Maintain IT glossary | C15: Implementation COT | D15: L2 | E15: MP | F15: 0 | L15: =NETWORKDAYS(J15,K15) -> 0 | P15: Manage IT governance framework
A16: Corporate IT body | B16: Maintain IT glossary | C16: Implementation LUS | D16: L2 | E16: MP | F16: 0 | L16: =NETWORKDAYS(J16,K16) -> 0 | P16: Manage IT governance framework
A17: Corporate IT body | B17: Manage enterprise architecture | C17: Total | D17: L1 | E17: MP | F17: 0 | J17: 46029 | K17: 46195 | L17: =NETWORKDAYS(J17,K17) -> 119 | P17: Manage enterprise architecture
A18: Corporate IT body | B18: Manage enterprise architecture | C18: Elaboration | D18: L1 | E18: MP | F18: 0 | G18: Hoermann Patrick (LLI) | H18: Gujral Parth (COB-COT-IT) | I18: Nussbaumer Florian (LBC) | J18: 46029 | K18: 46097 | L18: =NETWORKDAYS(J18,K18) -> 49 | O18: Scheduled | P18: Manage enterprise architecture
A19: Corporate IT body | B19: Manage enterprise architecture | C19: Implementation LIS | D19: L1 | E19: MP | F19: 0 | J19: 46127 | K19: 46195 | L19: =NETWORKDAYS(J19,K19) -> 49 | O19: Scheduled | P19: Manage enterprise architecture
A20: Corporate IT body | B20: Manage enterprise architecture | C20: Implementation COT | D20: L1 | E20: MP | F20: 0 | L20: =NETWORKDAYS(J20,K20) -> 0 | P20: Manage enterprise architecture
A21: Corporate IT body | B21: Manage enterprise architecture | C21: Implementation LUS | D21: L1 | E21: MP | F21: 0 | J21: 46142 | K21: 46142 | L21: =NETWORKDAYS(J21,K21) -> 1 | O21: Scheduled | P21: Manage enterprise architecture
A22: Corporate IT body | B22: Strategic architecture process | C22: Total | D22: L2 | E22: MP | F22: 0 | J22: 46142 | K22: 46142 | L22: =NETWORKDAYS(J22,K22) -> 1 | P22: Manage enterprise architecture
A23: Corporate IT body | B23: Strategic architecture process | C23: Elaboration | D23: L2 | E23: MP | F23: 0 | G23: Hoermann Patrick (LLI) | H23: Gujral Parth (COB-COT-IT) | I23: Nussbaumer Florian (LBC) | L23: =NETWORKDAYS(J23,K23) -> 0 | P23: Manage enterprise architecture
A24: Corporate IT body | B24: Strategic architecture process | C24: Implementation LIS | D24: L2 | E24: MP | F24: 0 | K24: 46142 | L24: =NETWORKDAYS(J24,K24) -> 32959 | P24: Manage enterprise architecture
A25: Corporate IT body | B25: Strategic architecture process | C25: Implementation COT | D25: L2 | E25: MP | F25: 0 | L25: =NETWORKDAYS(J25,K25) -> 0 | P25: Manage enterprise architecture
A26: Corporate IT body | B26: Strategic architecture process | C26: Implementation LUS | D26: L2 | E26: MP | F26: 0 | L26: =NETWORKDAYS(J26,K26) -> 0 | P26: Manage enterprise architecture
A27: ITSM | B27: Manage IT portfolio | C27: Total | D27: L1 | E27: MP | F27: 0 | J27: 45971 | K27: 46157 | L27: =NETWORKDAYS(J27,K27) -> 135 | P27: Manage IT portfolio
A28: ITSM | B28: Manage IT portfolio | C28: Elaboration | D28: L1 | E28: MP | F28: 0 | G28: Frank Maren (LIS);Kunz Christina (LIS-MHP Management- und IT Beratung GmbH) | H28: Rantou Anna (LIS) | J28: 45877 | K28: 46053 | L28: =NETWORKDAYS(J28,K28) -> 126 | N28: Delayed | O28: Elaboration in progress | P28: Manage IT portfolio
A29: ITSM | B29: Manage IT portfolio | C29: Implementation LIS | D29: L1 | E29: MP | F29: 0 | L29: =NETWORKDAYS(J29,K29) -> 0 | P29: Manage IT portfolio
A30: ITSM | B30: Manage IT portfolio | C30: Implementation COT | D30: L1 | E30: MP | F30: 0 | L30: =NETWORKDAYS(J30,K30) -> 0 | P30: Manage IT portfolio
A31: ITSM | B31: Manage IT portfolio | C31: Implementation LUS | D31: L1 | E31: MP | F31: 0 | J31: 46013 | K31: 46025 | L31: =NETWORKDAYS(J31,K31) -> 10 | O31: Scheduled | P31: Manage IT portfolio
A32: IT project management | B32: Manage IT project portfolio | C32: Total | D32: L2 | E32: MP | F32: 0 | J32: 45971 | K32: 46014 | L32: =NETWORKDAYS(J32,K32) -> 32 | P32: Manage IT portfolio
A33: IT project management | B33: Manage IT project portfolio | C33: Elaboration | D33: L2 | E33: MP | F33: 0 | G33: Frank Maren (LIS) | H33: Mühlbacher Christian (LIS) | I33: Rollinger Alexander (LIS) | J33: 45971 | K33: 46014 | L33: =NETWORKDAYS(J33,K33) -> 32 | N33: Delayed | O33: Elaboration in progress | P33: Manage IT portfolio
A34: IT project management | B34: Manage IT project portfolio | C34: Implementation LIS | D34: L2 | E34: MP | F34: 0 | L34: =NETWORKDAYS(J34,K34) -> 0 | P34: Manage IT portfolio
A35: IT project management | B35: Manage IT project portfolio | C35: Implementation COT | D35: L2 | E35: MP | F35: 0 | L35: =NETWORKDAYS(J35,K35) -> 0 | P35: Manage IT portfolio
A36: IT project management | B36: Manage IT project portfolio | C36: Implementation LUS | D36: L2 | E36: MP | F36: 0 | L36: =NETWORKDAYS(J36,K36) -> 0 | P36: Manage IT portfolio
A37: ITSM | B37: Manage IT service portfolio | C37: Total | D37: L2 | E37: MP | F37: 0 | J37: 46027 | K37: 46203 | L37: =NETWORKDAYS(J37,K37) -> 127 | P37: Manage IT portfolio
A38: ITSM | B38: Manage IT service portfolio | C38: Elaboration | D38: L2 | E38: MP | F38: 0 | G38: Frank Maren (LIS);Kunz Christina (LIS-MHP Management- und IT Beratung GmbH) | H38: Rantou Anna (LIS) | I38: Reiner Heiko (HAU-ITSA) | J38: 46027 | K38: 46111 | L38: =NETWORKDAYS(J38,K38) -> 61 | O38: Scheduled | P38: Manage IT portfolio
A39: ITSM | B39: Manage IT service portfolio | C39: Implementation LIS | D39: L2 | E39: MP | F39: 0 | J39: 46118 | K39: 46203 | L39: =NETWORKDAYS(J39,K39) -> 62 | O39: Scheduled | P39: Manage IT portfolio
A40: ITSM | B40: Manage IT service portfolio | C40: Implementation COT | D40: L2 | E40: MP | F40: 0 | L40: =NETWORKDAYS(J40,K40) -> 0 | P40: Manage IT portfolio
...

Sheet Tabelle1
A1: Datum | B1: Elaboration | C1: Implementation LIS | D1: Implementation LUS | E1: Implementation COT
A2: 45870 | B2: {=SUMPRODUCT((Task_Table1!$C$2:$C$571=$B$1)*(A2>Task_Table1!$J$2:$J$571)*(A2<Task_Table1!$K$2:$K$571))} -> 1 | C2: {=SUMPRODUCT((Task_Table1!$C$2:$C$571=$C$1)*(A2>Task_Table1!$J$2:$J$571)*(A2<Task_Table1!$K$2:$K$571))} -> 2 | D2: {=SUMPRODUCT((Task_Table1!$C$2:$C$571=$D$1)*(A2>Task_Table1!$J$2:$J$571)*(A2<Task_Table1!$K$2:$K$571))} -> 0 | E2: {=SUMPRODUCT((Task_Table1!$C$2:$C$571=$E$1)*(A2>Task_Table1!$J$2:$J$571)*(A2<Task_Table1!$K$2:$K$571))} -> 1
A3: 45871 | B3: {=SUMPRODUCT((Task_Table1!$C$2:$C$571=$B$1)*(A3>Task_Table1!$J$2:$J$571)*(A3<Task_Table1!$K$2:$K$571))} -> 2 | C3: {=SUMPRODUCT((Task_Table1!$C$2:$C$568=$C$1)*(A3>Task_Table1!$J$2:$J$568)*(A3<Task_Table1!$K$2:$K$568))} -> 2 | D3: {=SUMPRODUCT((Task_Table1!$C$2:$C$571=$D$1)*(A3>Task_Table1!$J$2:$J$571)*(A3<Task_Table1!$K$2:$K$571))} -> 0 | E3: {=SUMPRODUCT((Task_Table1!$C$2:$C$571=$E$1)*(A3>Task_Table1!$J$2:$J$571)*(A3<Task_Table1!$K$2:$K$571))} -> 1
A4: 45872 | B4: {=SUMPRODUCT((Task_Table1!$C$2:$C$571=$B$1)*(A4>Task_Table1!$J$2:$J$571)*(A4<Task_Table1!$K$2:$K$571))} -> 2 | C4: {=SUMPRODUCT((Task_Table1!$C$2:$C$568=$C$1)*(A4>Task_Table1!$J$2:$J$568)*(A4<Task_Table1!$K$2:$K$568))} -> 2 | D4: {=SUMPRODUCT((Task_Table1!$C$2:$C$571=$D$1)*(A4>Task_Table1!$J$2:$J$571)*(A4<Task_Table1!$K$2:$K$571))} -> 0 | E4: {=SUMPRODUCT((Task_Table1!$C$2:$C$571=$E$1)*(A4>Task_Table1!$J$2:$J$571)*(A4<Task_Table1!$K$2:$K$571))} -> 1
A5: 45873 | B5: {=SUMPRODUCT((Task_Table1!$C$2:$C$571=$B$1)*(A5>Task_Table1!$J$2:$J$571)*(A5<Task_Table1!$K$2:$K$571))} -> 2 | C5: {=SUMPRODUCT((Task_Table1!$C$2:$C$568=$C$1)*(A5>Task_Table1!$J$2:$J$568)*(A5<Task_Table1!$K$2:$K$568))} -> 2 | D5: {=SUMPRODUCT((Task_Table1!$C$2:$C$571=$D$1)*(A5>Task_Table1!$J$2:$J$571)*(A5<Task_Table1!$K$2:$K$571))} -> 0 | E5: {=SUMPRODUCT((Task_Table1!$C$2:$C$571=$E$1)*(A5>Task_Table1!$J$2:$J$571)*(A5<Task_Table1!$K$2:$K$571))} -> 1
A6: 45874 | B6: {=SUMPRODUCT((Task_Table1!$C$2:$C$571=$B$1)*(A6>Task_Table1!$J$2:$J$571)*(A6<Task_Table1!$K$2:$K$571))} -> 2 | C6: {=SUMPRODUCT((Task_Table1!$C$2:$C$568=$C$1)*(A6>Task_Table1!$J$2:$J$568)*(A6<Task_Table1!$K$2:$K$568))} -> 2 | D6: {=SUMPRODUCT((Task_Table1!$C$2:$C$571=$D$1)*(A6>Task_Table1!$J$2:$J$571)*(A6<Task_Table1!$K$2:$K$571))} -> 0 | E6: {=SUMPRODUCT((Task_Table1!$C$2:$C$571=$E$1)*(A6>Task_Table1!$J$2:$J$571)*(A6<Task_Table1!$K$2:$K$571))} -> 1
A7: 45875 | B7: {=SUMPRODUCT((Task_Table1!$C$2:$C$571=$B$1)*(A7>Task_Table1!$J$2:$J$571)*(A7<Task_Table1!$K$2:$K$571))} -> 2 | C7: {=SUMPRODUCT((Task_Table1!$C$2:$C$568=$C$1)*(A7>Task_Table1!$J$2:$J$568)*(A7<Task_Table1!$K$2:$K$568))} -> 2 | D7: {=SUMPRODUCT((Task_Table1!$C$2:$C$571=$D$1)*(A7>Task_Table1!$J$2:$J$571)*(A7<Task_Table1!$K$2:$K$571))} -> 0 | E7: {=SUMPRODUCT((Task_Table1!$C$2:$C$571=$E$1)*(A7>Task_Table1!$J$2:$J$571)*(A7<Task_Table1!$K$2:$K$571))} -> 1
A8: 45876 | B8: {=SUMPRODUCT((Task_Table1!$C$2:$C$571=$B$1)*(A8>Task_Table1!$J$2:$J$571)*(A8<Task_Table1!$K$2:$K$571))} -> 2 | C8: {=SUMPRODUCT((Task_Table1!$C$2:$C$568=$C$1)*(A8>Task_Table1!$J$2:$J$568)*(A8<Task_Table1!$K$2:$K$568))} -> 2 | D8: {=SUMPRODUCT((Task_Table1!$C$2:$C$571=$D$1)*(A8>Task_Table1!$J$2:$J$571)*(A8<Task_Table1!$K$2:$K$571))} -> 0 | E8: {=SUMPRODUCT((Task_Table1!$C$2:$C$571=$E$1)*(A8>Task_Table1!$J$2:$J$571)*(A8<Task_Table1!$K$2:$K$571))} -> 1
A9: 45877 | B9: {=SUMPRODUCT((Task_Table1!$C$2:$C$571=$B$1)*(A9>Task_Table1!$J$2:$J$571)*(A9<Task_Table1!$K$2:$K$571))} -> 2 | C9: {=SUMPRODUCT((Task_Table1!$C$2:$C$568=$C$1)*(A9>Task_Table1!$J$2:$J$568)*(A9<Task_Table1!$K$2:$K$568))} -> 2 | D9: {=SUMPRODUCT((Task_Table1!$C$2:$C$571=$D$1)*(A9>Task_Table1!$J$2:$J$571)*(A9<Task_Table1!$K$2:$K$571))} -> 0 | E9: {=SUMPRODUCT((Task_Table1!$C$2:$C$571=$E$1)*(A9>Task_Table1!$J$2:$J$571)*(A9<Task_Table1!$K$2:$K$571))} -> 1
A10: 45878 | B10: {=SUMPRODUCT((Task_Table1!$C$2:$C$571=$B$1)*(A10>Task_Table1!$J$2:$J$571)*(A10<Task_Table1!$K$2:$K$571))} -> 3 | C10: {=SUMPRODUCT((Task_Table1!$C$2:$C$568=$C$1)*(A10>Task_Table1!$J$2:$J$568)*(A10<Task_Table1!$K$2:$K$568))} -> 2 | D10: {=SUMPRODUCT((Task_Table1!$C$2:$C$571=$D$1)*(A10>Task_Table1!$J$2:$J$571)*(A10<Task_Table1!$K$2:$K$571))} -> 0 | E10: {=SUMPRODUCT((Task_Table1!$C$2:$C$571=$E$1)*(A10>Task_Table1!$J$2:$J$571)*(A10<Task_Table1!$K$2:$K$571))} -> 1
A11: 45879 | B11: {=SUMPRODUCT((Task_Table1!$C$2:$C$571=$B$1)*(A11>Task_Table1!$J$2:$J$571)*(A11<Task_Table1!$K$2:$K$571))} -> 3 | C11: {=SUMPRODUCT((Task_Table1!$C$2:$C$568=$C$1)*(A11>Task_Table1!$J$2:$J$568)*(A11<Task_Table1!$K$2:$K$568))} -> 2 | D11: {=SUMPRODUCT((Task_Table1!$C$2:$C$571=$D$1)*(A11>Task_Table1!$J$2:$J$571)*(A11<Task_Table1!$K$2:$K$571))} -> 0 | E11: {=SUMPRODUCT((Task_Table1!$C$2:$C$571=$E$1)*(A11>Task_Table1!$J$2:$J$571)*(A11<Task_Table1!$K$2:$K$571))} -> 1
A12: 45880 | B12: {=SUMPRODUCT((Task_Table1!$C$2:$C$571=$B$1)*(A12>Task_Table1!$J$2:$J$571)*(A12<Task_Table1!$K$2:$K$571))} -> 3 | C12: {=SUMPRODUCT((Task_Table1!$C$2:$C$568=$C$1)*(A12>Task_Table1!$J$2:$J$568)*(A12<Task_Table1!$K$2:$K$568))} -> 2 | D12: {=SUMPRODUCT((Task_Table1!$C$2:$C$571=$D$1)*(A12>Task_Table1!$J$2:$J$571)*(A12<Task_Table1!$K$2:$K$571))} -> 0 | E12: {=SUMPRODUCT((Task_Table1!$C$2:$C$571=$E$1)*(A12>Task_Table1!$J$2:$J$571)*(A12<Task_Table1!$K$2:$K$571))} -> 1
A13: 45881 | B13: {=SUMPRODUCT((Task_Table1!$C$2:$C$571=$B$1)*(A13>Task_Table1!$J$2:$J$571)*(A13<Task_Table1!$K$2:$K$571))} -> 3 | C13: {=SUMPRODUCT((Task_Table1!$C$2:$C$568=$C$1)*(A13>Task_Table1!$J$2:$J$568)*(A13<Task_Table1!$K$2:$K$568))} -> 2 | D13: {=SUMPRODUCT((Task_Table1!$C$2:$C$571=$D$1)*(A13>Task_Table1!$J$2:$J$571)*(A13<Task_Table1!$K$2:$K$571))} -> 0 | E13: {=SUMPRODUCT((Task_Table1!$C$2:$C$571=$E$1)*(A13>Task_Table1!$J$2:$J$571)*(A13<Task_Table1!$K$2:$K$571))} -> 1
A14: 45882 | B14: {=SUMPRODUCT((Task_Table1!$C$2:$C$571=$B$1)*(A14>Task_Table1!$J$2:$J$571)*(A14<Task_Table1!$K$2:$K$571))} -> 3 | C14: {=SUMPRODUCT((Task_Table1!$C$2:$C$568=$C$1)*(A14>Task_Table1!$J$2:$J$568)*(A14<Task_Table1!$K$2:$K$568))} -> 2 | D14: {=SUMPRODUCT((Task_Table1!$C$2:$C$571=$D$1)*(A14>Task_Table1!$J$2:$J$571)*(A14<Task_Table1!$K$2:$K$571))} -> 0 | E14: {=SUMPRODUCT((Task_Table1!$C$2:$C$571=$E$1)*(A14>Task_Table1!$J$2:$J$571)*(A14<Task_Table1!$K$2:$K$571))} -> 1
... A520: 46388 | B520: {=SUMPRODUCT((Task_Table1!$C$2:$C$571=$B$1)*(A520>Task_Table1!$J$2:$J$571)*(A520<Task_Table1!$K$2:$K$571))} -> 1 | C520: {=SUMPRODUCT((Task_Table1!$C$2:$C$568=$C$1)*(A520>Task_Table1!$J$2:$J$568)*(A520<Task_Table1!$K$2:$K$568))} -> 0 | D520: {=SUMPRODUCT((Task_Table1!$C$2:$C$571=$D$1)*(A520>Task_Table1!$J$2:$J$571)*(A520<Task_Table1!$K$2:$K$571))} -> 0 | E520: {=SUMPRODUCT((Task_Table1!$C$2:$C$571=$E$1)*(A520>Task_Table1!$J$2:$J$571)*(A520<Task_Table1!$K$2:$K$571))} -> 0

Sheet Task_Table_02_26
A1: Initiative | B1: Process | C1: Phase | D1: Process level | E1: Process Group | F1: % Work Complete | G1: IT Process Consultant | H1: Responsible | I1: IT Process Manager | L1: Duration2 | M1: Process approval date | N1: Actual Phase | O1: Planned phase | P1: Associated Process on L1
A2: Corporate IT body | B2: Manage IT strategy | C2: Total | D2: L1 | E2: MP | F2: 0.15 | J2: 46029 | K2: 46203 | L2: =NETWORKDAYS(J2,K2) -> 125 | M2: 45953 | P2: Manage IT strategy
A3: Corporate IT body | B3: Manage IT strategy | C3: Elaboration | D3: L1 | E3: MP | F3: 0.15 | G3: Kunz Christina (LIS-MHP Management- und IT Beratung GmbH) | H3: Felder Max (LLI) | I3: Mielenz Thomas (LMT) | J3: 46029 | K3: 46097 | L3: =NETWORKDAYS(J3,K3) -> 49 | N3: Elaboration in progress | O3: Elaboration in progress | P3: Manage IT strategy
A4: Corporate IT body | B4: Manage IT strategy | C4: Implementation LIS | D4: L1 | E4: MP | F4: 0 | J4: 46127 | K4: 46203 | L4: =NETWORKDAYS(J4,K4) -> 55 | O4: Scheduled | P4: Manage IT strategy
A5: Corporate IT body | B5: Manage IT strategy | C5: Implementation COT | D5: L1 | E5: MP | F5: 0 | L5: =NETWORKDAYS(J5,K5) -> 0 | P5: Manage IT strategy
A6: Corporate IT body | B6: Manage IT strategy | C6: Implementation LUS | D6: L1 | E6: MP | F6: 0 | L6: =NETWORKDAYS(J6,K6) -> 0 | P6: Manage IT strategy
A7: Corporate IT body | B7: Manage IT governance framework | C7: Total | D7: L1 | E7: MP | F7: 0 | J7: 46029 | K7: 46203 | L7: =NETWORKDAYS(J7,K7) -> 125 | P7: Manage IT governance framework
A8: Corporate IT body | B8: Manage IT governance framework | C8: Elaboration | D8: L1 | E8: MP | F8: 0 | G8: Kunz Christina (LIS-MHP Management- und IT Beratung GmbH) | H8: Felder Max (LLI) | I8: Mielenz Thomas (LMT) | J8: 46029 | K8: 46097 | L8: =NETWORKDAYS(J8,K8) -> 49 | N8: Delayed | O8: Elaboration in progress | P8: Manage IT governance framework
A9: Corporate IT body | B9: Manage IT governance framework | C9: Implementation LIS | D9: L1 | E9: MP | F9: 0 | J9: 46127 | K9: 46203 | L9: =NETWORKDAYS(J9,K9) -> 55 | O9: Scheduled | P9: Manage IT governance framework
A10: Corporate IT body | B10: Manage IT governance framework | C10: Implementation COT | D10: L1 | E10: MP | F10: 0 | L10: =NETWORKDAYS(J10,K10) -> 0 | P10: Manage IT governance framework
A11: Corporate IT body | B11: Manage IT governance framework | C11: Implementation LUS | D11: L1 | E11: MP | F11: 0 | L11: =NETWORKDAYS(J11,K11) -> 0 | P11: Manage IT governance framework
A12: Corporate IT body | B12: Maintain IT glossary | C12: Total | D12: L2 | E12: MP | F12: 0 | L12: =NETWORKDAYS(J12,K12) -> 0 | P12: Manage IT governance framework
A13: Corporate IT body | B13: Maintain IT glossary | C13: Elaboration | D13: L2 | E13: MP | F13: 0 | G13: Kunz Christina (LIS-MHP Management- und IT Beratung GmbH) | H13: Felder Max (LLI) | I13: Mielenz Thomas (LMT) | J13: 46029 | P13: Manage IT governance framework
A14: Corporate IT body | B14: Maintain IT glossary | C14: Implementation LIS | D14: L2 | E14: MP | F14: 0 | J14: 46029 | K14: 46039 | L14: =NETWORKDAYS(J14,K14) -> 8 | N14: Delayed | O14: Implementation LIS Done | P14: Manage IT governance framework
A15: Corporate IT body | B15: Maintain IT glossary | C15: Implementation COT | D15: L2 | E15: MP | F15: 0 | J15: 46029 | P15: Manage IT governance framework
A16: Corporate IT body | B16: Maintain IT glossary | C16: Implementation LUS | D16: L2 | E16: MP | F16: 0 | L16: =NETWORKDAYS(J16,K16) -> 0 | P16: Manage IT governance framework
A17: Corporate IT body | B17: Manage enterprise architecture | C17: Total | D17: L1 | E17: MP | F17: 0 | J17: 45946 | K17: 46205 | L17: =NETWORKDAYS(J17,K17) -> 186 | P17: Manage enterprise architecture
A18: Corporate IT body | B18: Manage enterprise architecture | C18: Elaboration | D18: L1 | E18: MP | F18: 0 | G18: Hoermann Patrick (LLI) | H18: Gujral Parth (COB-COT-IT) | I18: Nussbaumer Florian (LBC) | J18: 46062 | K18: 46136 | L18: =NETWORKDAYS(J18,K18) -> 55 | N18: Delayed | O18: Elaboration in progress | P18: Manage enterprise architecture
A19: Corporate IT body | B19: Manage enterprise architecture | C19: Implementation LIS | D19: L1 | E19: MP | F19: 0 | J19: 46136 | K19: 46205 | L19: =NETWORKDAYS(J19,K19) -> 50 | O19: Scheduled | P19: Manage enterprise architecture
A20: Corporate IT body | B20: Manage enterprise architecture | C20: Implementation COT | D20: L1 | E20: MP | F20: 0 | J20: 46062 | K20: 46062 | L20: =NETWORKDAYS(J20,K20) -> 1 | N20: Delayed | O20: Implementation COT Done | P20: Manage enterprise architecture
A21: Corporate IT body | B21: Manage enterprise architecture | C21: Implementation LUS | D21: L1 | E21: MP | F21: 0 | J21: 46142 | K21: 46142 | L21: =NETWORKDAYS(J21,K21) -> 1 | O21: Scheduled | P21: Manage enterprise architecture
A22: Corporate IT body | B22: Strategic architecture process | C22: Total | D22: L2 | E22: MP | F22: 0 | J22: 45946 | K22: 46142 | L22: =NETWORKDAYS(J22,K22) -> 141 | P22: Manage enterprise architecture
A23: Corporate IT body | B23: Strategic architecture process | C23: Elaboration | D23: L2 | E23: MP | F23: 0 | G23: Hoermann Patrick (LLI) | H23: Gujral Parth (COB-COT-IT) | I23: Nussbaumer Florian (LBC) | J23: 45946 | K23: 45946 | L23: =NETWORKDAYS(J23,K23) -> 1 | N23: Delayed | O23: Elaboration Done | P23: Manage enterprise architecture
A24: Corporate IT body | B24: Strategic architecture process | C24: Implementation LIS | D24: L2 | E24: MP | F24: 0 | K24: 46142 | P24: Manage enterprise architecture
A25: Corporate IT body | B25: Strategic architecture process | C25: Implementation COT | D25: L2 | E25: MP | F25: 0 | J25: 45946 | K25: 45946 | L25: =NETWORKDAYS(J25,K25) -> 1 | N25: Delayed | O25: Implementation COT Done | P25: Manage enterprise architecture
A26: Corporate IT body | B26: Strategic architecture process | C26: Implementation LUS | D26: L2 | E26: MP | F26: 0 | J26: 45946 | K26: 45946 | L26: =NETWORKDAYS(J26,K26) -> 1 | N26: Delayed | O26: Implementation LUS Done | P26: Manage enterprise architecture
A27: ITSM | B27: Manage IT portfolio | C27: Total | D27: L1 | E27: MP | F27: 0.11 | J27: 45971 | K27: 46157 | L27: =NETWORKDAYS(J27,K27) -> 135 | P27: Manage IT portfolio
A28: ITSM | B28: Manage IT portfolio | C28: Elaboration | D28: L1 | E28: MP | F28: 0 | G28: Frank Maren (LIS);Kunz Christina (LIS-MHP Management- und IT Beratung GmbH) | H28: ? | J28: 45972 | K28: 46051 | L28: =NETWORKDAYS(J28,K28) -> 58 | N28: Delayed | O28: Elaboration Done | P28: Manage IT portfolio
A29: ITSM | B29: Manage IT portfolio | C29: Implementation LIS | D29: L1 | E29: MP | F29: 0 | L29: =NETWORKDAYS(J29,K29) -> 0 | P29: Manage IT portfolio
A30: ITSM | B30: Manage IT portfolio | C30: Implementation COT | D30: L1 | E30: MP | F30: 0 | J30: 45971 | P30: Manage IT portfolio
A31: ITSM | B31: Manage IT portfolio | C31: Implementation LUS | D31: L1 | E31: MP | F31: 0 | L31: =NETWORKDAYS(J31,K31) -> 0 | P31: Manage IT portfolio
A32: IT project management | B32: Manage IT project portfolio | C32: Total | D32: L2 | E32: MP | F32: 1 | J32: 45939 | K32: 46001 | L32: =NETWORKDAYS(J32,K32) -> 45 | P32: Manage IT portfolio
A33: IT project management | B33: Manage IT project portfolio | C33: Elaboration | D33: L2 | E33: MP | F33: 1 | G33: Frank Maren (LIS) | H33: Mühlbacher Christian (LIS) | I33: Rollinger Alexander (LIS) | J33: 45971 | K33: 46001 | L33: =NETWORKDAYS(J33,K33) -> 23 | M33: 46050 | N33: Elaboration Done | O33: Elaboration Done | P33: Manage IT portfolio
A34: IT project management | B34: Manage IT project portfolio | C34: Implementation LIS | D34: L2 | E34: MP | F34: 0 | J34: 45939 | P34: Manage IT portfolio
A35: IT project management | B35: Manage IT project portfolio | C35: Implementation COT | D35: L2 | E35: MP | F35: 0 | L35: =NETWORKDAYS(J35,K35) -> 0 | P35: Manage IT portfolio
A36: IT project management | B36: Manage IT project portfolio | C36: Implementation LUS | D36: L2 | E36: MP | F36: 0 | L36: =NETWORKDAYS(J36,K36) -> 0 | P36: Manage IT portfolio
A37: ITSM | B37: Manage IT service portfolio | C37: Total | D37: L2 | E37: MP | F37: 0 | J37: 46076 | K37: 46203 | L37: =NETWORKDAYS(J37,K37) -> 92 | P37: Manage IT portfolio
A38: ITSM | B38: Manage IT service portfolio | C38: Elaboration | D38: L2 | E38: MP | F38: 0 | G38: Frank Maren (LIS);Kunz Christina (LIS-MHP Management- und IT Beratung GmbH) | H38: ? | I38: Reiner Heiko (HAU-ITSA) | J38: 46076 | K38: 46118 | L38: =NETWORKDAYS(J38,K38) -> 31 | O38: Scheduled | P38: Manage IT portfolio
A39: ITSM | B39: Manage IT service portfolio | C39: Implementation LIS | D39: L2 | E39: MP | F39: 0 | J39: 46118 | K39: 46203 | L39: =NETWORKDAYS(J39,K39) -> 62 | O39: Scheduled | P39: Manage IT portfolio
A40: ITSM | B40: Manage IT service portfolio | C40: Implementation COT | D40: L2 | E40: MP | F40: 0 | L40: =NETWORKDAYS(J40,K40) -> 0 | P40: Manage IT portfolio
...

Sheet Date_table_02_26
A1: Datum | B1: Elaboration | C1: Implementation LIS | D1: Implementation LUS | E1: Implementation COT
A2: 45870 | B2: {=SUMPRODUCT((Task_Table_02_26!$C$2:$C$571=$B$1)*(A2>Task_Table_02_26!$J$2:$J$571)*(A2<Task_Table_02_26!$K$2:$K$571))} -> 0 | C2: {=SUMPRODUCT((Task_Table_02_26!$C$2:$C$571=$C$1)*(A2>Task_Table_02_26!$J$2:$J$571)*(A2<Task_Table_02_26!$K$2:$K$571))} -> 2 | D2: {=SUMPRODUCT((Task_Table_02_26!$C$2:$C$571=$D$1)*(A2>Task_Table_02_26!$J$2:$J$571)*(A2<Task_Table_02_26!$K$2:$K$571))} -> 0 | E2: {=SUMPRODUCT((Task_Table_02_26!$C$2:$C$571=$E$1)*(A2>Task_Table_02_26!$J$2:$J$571)*(A2<Task_Table_02_26!$K$2:$K$571))} -> 0
A3: 45871 | B3: {=SUMPRODUCT((Task_Table_02_26!$C$2:$C$571=$B$1)*(A3>Task_Table_02_26!$J$2:$J$571)*(A3<Task_Table_02_26!$K$2:$K$571))} -> 1 | C3: {=SUMPRODUCT((Task_Table_02_26!$C$2:$C$571=$C$1)*(A3>Task_Table_02_26!$J$2:$J$571)*(A3<Task_Table_02_26!$K$2:$K$571))} -> 2 | D3: {=SUMPRODUCT((Task_Table_02_26!$C$2:$C$571=$D$1)*(A3>Task_Table_02_26!$J$2:$J$571)*(A3<Task_Table_02_26!$K$2:$K$571))} -> 0 | E3: {=SUMPRODUCT((Task_Table_02_26!$C$2:$C$571=$E$1)*(A3>Task_Table_02_26!$J$2:$J$571)*(A3<Task_Table_02_26!$K$2:$K$571))} -> 0
A4: 45872 | B4: {=SUMPRODUCT((Task_Table_02_26!$C$2:$C$571=$B$1)*(A4>Task_Table_02_26!$J$2:$J$571)*(A4<Task_Table_02_26!$K$2:$K$571))} -> 1 | C4: {=SUMPRODUCT((Task_Table_02_26!$C$2:$C$571=$C$1)*(A4>Task_Table_02_26!$J$2:$J$571)*(A4<Task_Table_02_26!$K$2:$K$571))} -> 2 | D4: {=SUMPRODUCT((Task_Table_02_26!$C$2:$C$571=$D$1)*(A4>Task_Table_02_26!$J$2:$J$571)*(A4<Task_Table_02_26!$K$2:$K$571))} -> 0 | E4: {=SUMPRODUCT((Task_Table_02_26!$C$2:$C$571=$E$1)*(A4>Task_Table_02_26!$J$2:$J$571)*(A4<Task_Table_02_26!$K$2:$K$571))} -> 0
A5: 45873 | B5: {=SUMPRODUCT((Task_Table_02_26!$C$2:$C$571=$B$1)*(A5>Task_Table_02_26!$J$2:$J$571)*(A5<Task_Table_02_26!$K$2:$K$571))} -> 1 | C5: {=SUMPRODUCT((Task_Table_02_26!$C$2:$C$571=$C$1)*(A5>Task_Table_02_26!$J$2:$J$571)*(A5<Task_Table_02_26!$K$2:$K$571))} -> 2 | D5: {=SUMPRODUCT((Task_Table_02_26!$C$2:$C$571=$D$1)*(A5>Task_Table_02_26!$J$2:$J$571)*(A5<Task_Table_02_26!$K$2:$K$571))} -> 0 | E5: {=SUMPRODUCT((Task_Table_02_26!$C$2:$C$571=$E$1)*(A5>Task_Table_02_26!$J$2:$J$571)*(A5<Task_Table_02_26!$K$2:$K$571))} -> 0
A6: 45874 | B6: {=SUMPRODUCT((Task_Table_02_26!$C$2:$C$571=$B$1)*(A6>Task_Table_02_26!$J$2:$J$571)*(A6<Task_Table_02_26!$K$2:$K$571))} -> 1 | C6: {=SUMPRODUCT((Task_Table_02_26!$C$2:$C$571=$C$1)*(A6>Task_Table_02_26!$J$2:$J$571)*(A6<Task_Table_02_26!$K$2:$K$571))} -> 2 | D6: {=SUMPRODUCT((Task_Table_02_26!$C$2:$C$571=$D$1)*(A6>Task_Table_02_26!$J$2:$J$571)*(A6<Task_Table_02_26!$K$2:$K$571))} -> 0 | E6: {=SUMPRODUCT((Task_Table_02_26!$C$2:$C$571=$E$1)*(A6>Task_Table_02_26!$J$2:$J$571)*(A6<Task_Table_02_26!$K$2:$K$571))} -> 0
A7: 45875 | B7: {=SUMPRODUCT((Task_Table_02_26!$C$2:$C$571=$B$1)*(A7>Task_Table_02_26!$J$2:$J$571)*(A7<Task_Table_02_26!$K$2:$K$571))} -> 1 | C7: {=SUMPRODUCT((Task_Table_02_26!$C$2:$C$571=$C$1)*(A7>Task_Table_02_26!$J$2:$J$571)*(A7<Task_Table_02_26!$K$2:$K$571))} -> 2 | D7: {=SUMPRODUCT((Task_Table_02_26!$C$2:$C$571=$D$1)*(A7>Task_Table_02_26!$J$2:$J$571)*(A7<Task_Table_02_26!$K$2:$K$571))} -> 0 | E7: {=SUMPRODUCT((Task_Table_02_26!$C$2:$C$571=$E$1)*(A7>Task_Table_02_26!$J$2:$J$571)*(A7<Task_Table_02_26!$K$2:$K$571))} -> 0
A8: 45876 | B8: {=SUMPRODUCT((Task_Table_02_26!$C$2:$C$571=$B$1)*(A8>Task_Table_02_26!$J$2:$J$571)*(A8<Task_Table_02_26!$K$2:$K$571))} -> 1 | C8: {=SUMPRODUCT((Task_Table_02_26!$C$2:$C$571=$C$1)*(A8>Task_Table_02_26!$J$2:$J$571)*(A8<Task_Table_02_26!$K$2:$K$571))} -> 2 | D8: {=SUMPRODUCT((Task_Table_02_26!$C$2:$C$571=$D$1)*(A8>Task_Table_02_26!$J$2:$J$571)*(A8<Task_Table_02_26!$K$2:$K$571))} -> 0 | E8: {=SUMPRODUCT((Task_Table_02_26!$C$2:$C$571=$E$1)*(A8>Task_Table_02_26!$J$2:$J$571)*(A8<Task_Table_02_26!$K$2:$K$571))} -> 0
A9: 45877 | B9: {=SUMPRODUCT((Task_Table_02_26!$C$2:$C$571=$B$1)*(A9>Task_Table_02_26!$J$2:$J$571)*(A9<Task_Table_02_26!$K$2:$K$571))} -> 1 | C9: {=SUMPRODUCT((Task_Table_02_26!$C$2:$C$571=$C$1)*(A9>Task_Table_02_26!$J$2:$J$571)*(A9<Task_Table_02_26!$K$2:$K$571))} -> 2 | D9: {=SUMPRODUCT((Task_Table_02_26!$C$2:$C$571=$D$1)*(A9>Task_Table_02_26!$J$2:$J$571)*(A9<Task_Table_02_26!$K$2:$K$571))} -> 0 | E9: {=SUMPRODUCT((Task_Table_02_26!$C$2:$C$571=$E$1)*(A9>Task_Table_02_26!$J$2:$J$571)*(A9<Task_Table_02_26!$K$2:$K$571))} -> 0
A10: 45878 | B10: {=SUMPRODUCT((Task_Table_02_26!$C$2:$C$571=$B$1)*(A10>Task_Table_02_26!$J$2:$J$571)*(A10<Task_Table_02_26!$K$2:$K$571))} -> 1 | C10: {=SUMPRODUCT((Task_Table_02_26!$C$2:$C$571=$C$1)*(A10>Task_Table_02_26!$J$2:$J$571)*(A10<Task_Table_02_26!$K$2:$K$571))} -> 2 | D10: {=SUMPRODUCT((Task_Table_02_26!$C$2:$C$571=$D$1)*(A10>Task_Table_02_26!$J$2:$J$571)*(A10<Task_Table_02_26!$K$2:$K$571))} -> 0 | E10: {=SUMPRODUCT((Task_Table_02_26!$C$2:$C$571=$E$1)*(A10>Task_Table_02_26!$J$2:$J$571)*(A10<Task_Table_02_26!$K$2:$K$571))} -> 0
A11: 45879 | B11: {=SUMPRODUCT((Task_Table_02_26!$C$2:$C$571=$B$1)*(A11>Task_Table_02_26!$J$2:$J$571)*(A11<Task_Table_02_26!$K$2:$K$571))} -> 1 | C11: {=SUMPRODUCT((Task_Table_02_26!$C$2:$C$571=$C$1)*(A11>Task_Table_02_26!$J$2:$J$571)*(A11<Task_Table_02_26!$K$2:$K$571))} -> 2 | D11: {=SUMPRODUCT((Task_Table_02_26!$C$2:$C$571=$D$1)*(A11>Task_Table_02_26!$J$2:$J$571)*(A11<Task_Table_02_26!$K$2:$K$571))} -> 0 | E11: {=SUMPRODUCT((Task_Table_02_26!$C$2:$C$571=$E$1)*(A11>Task_Table_02_26!$J$2:$J$571)*(A11<Task_Table_02_26!$K$2:$K$571))} -> 0
A12: 45880 | B12: {=SUMPRODUCT((Task_Table_02_26!$C$2:$C$571=$B$1)*(A12>Task_Table_02_26!$J$2:$J$571)*(A12<Task_Table_02_26!$K$2:$K$571))} -> 1 | C12: {=SUMPRODUCT((Task_Table_02_26!$C$2:$C$571=$C$1)*(A12>Task_Table_02_26!$J$2:$J$571)*(A12<Task_Table_02_26!$K$2:$K$571))} -> 2 | D12: {=SUMPRODUCT((Task_Table_02_26!$C$2:$C$571=$D$1)*(A12>Task_Table_02_26!$J$2:$J$571)*(A12<Task_Table_02_26!$K$2:$K$571))} -> 0 | E12: {=SUMPRODUCT((Task_Table_02_26!$C$2:$C$571=$E$1)*(A12>Task_Table_02_26!$J$2:$J$571)*(A12<Task_Table_02_26!$K$2:$K$571))} -> 0
A13: 45881 | B13: {=SUMPRODUCT((Task_Table_02_26!$C$2:$C$571=$B$1)*(A13>Task_Table_02_26!$J$2:$J$571)*(A13<Task_Table_02_26!$K$2:$K$571))} -> 1 | C13: {=SUMPRODUCT((Task_Table_02_26!$C$2:$C$571=$C$1)*(A13>Task_Table_02_26!$J$2:$J$571)*(A13<Task_Table_02_26!$K$2:$K$571))} -> 2 | D13: {=SUMPRODUCT((Task_Table_02_26!$C$2:$C$571=$D$1)*(A13>Task_Table_02_26!$J$2:$J$571)*(A13<Task_Table_02_26!$K$2:$K$571))} -> 0 | E13: {=SUMPRODUCT((Task_Table_02_26!$C$2:$C$571=$E$1)*(A13>Task_Table_02_26!$J$2:$J$571)*(A13<Task_Table_02_26!$K$2:$K$571))} -> 0
... A520: 46388 | B520: {=SUMPRODUCT((Task_Table_02_26!$C$2:$C$571=$B$1)*(A520>Task_Table_02_26!$J$2:$J$571)*(A520<Task_Table_02_26!$K$2:$K$571))} -> 1 | C520: {=SUMPRODUCT((Task_Table_02_26!$C$2:$C$571=$C$1)*(A520>Task_Table_02_26!$J$2:$J$571)*(A520<Task_Table_02_26!$K$2:$K$571))} -> 0 | D520: {=SUMPRODUCT((Task_Table_02_26!$C$2:$C$571=$D$1)*(A520>Task_Table_02_26!$J$2:$J$571)*(A520<Task_Table_02_26!$K$2:$K$571))} -> 0 | E520: {=SUMPRODUCT((Task_Table_02_26!$C$2:$C$571=$E$1)*(A520>Task_Table_02_26!$J$2:$J$571)*(A520<Task_Table_02_26!$K$2:$K$571))} -> 0

Sheet Task_table_03_26
A1: Initiative | B1: Process | C1: Phase | D1: Process level | E1: Process Group | F1: % Arbeit abgeschlossen | G1: IT Process Consultant | H1: IT Process Initiative Lead | I1: IT Process Manager | J1: Anfang | K1: Ende | L1: Dauer2 | M1: Process Approval Date | N1: Actual Phase | O1: Planned phase | P1: Associated Process on L1 | R1: 📌 Analyse
A2: Corporate IT body | B2: Manage IT strategy | C2: Total | D2: L1 | E2: MP | F2: 0.5 | J2: 46055 | K2: 46232 | L2: 128 | M2: Mit 06.05.26 | O2: 1 | P2: Manage IT strategy | R2: Prozesse in Elaboration | S2: 39
A3: Corporate IT body | B3: Manage IT strategy | C3: Elaboration | D3: L1 | E3: MP | F3: 0.5 | G3: Kreis Andreas (LLI) | H3: Felder Max (LLI) | I3: Mielenz Thomas (LMT) | J3: 46055 | K3: 46142 | L3: 64 | M3: NV | N3: Elaboration in progress | O3: Elaboration in progress | P3: Manage IT strategy
A4: Corporate IT body | B4: Manage IT strategy | C4: Implementation LIS | D4: L1 | E4: MP | F4: 0 | J4: 46156 | K4: 46232 | L4: 55 | M4: NV | O4: Scheduled | P4: Manage IT strategy
A5: Corporate IT body | B5: Manage IT strategy | C5: Implementation COT | D5: L1 | E5: MP | F5: 0 | J5: ? | K5: ? | L5: 0 | M5: NV | P5: Manage IT strategy
A6: Corporate IT body | B6: Manage IT strategy | C6: Implementation LUS | D6: L1 | E6: MP | F6: 0 | J6: ? | K6: ? | L6: 0 | M6: NV | P6: Manage IT strategy
A7: Corporate IT body | B7: Manage IT governance framework | C7: Total | D7: L1 | E7: MP | F7: 0.5 | J7: 46029 | K7: 46265 | L7: 169 | M7: NV | P7: Manage IT governance framework
A8: Corporate IT body | B8: Manage IT governance framework | C8: Elaboration | D8: L1 | E8: MP | F8: 0.5 | G8: Kunz Christina (LIS-MHP Management- und IT Beratung GmbH);Kreis Andreas (LLI) | H8: Felder Max (LLI) | I8: Mielenz Thomas (LMT) | J8: 46097 | K8: 46163 | L8: 49 | M8: NV | N8: Elaboration in progress | O8: Elaboration in progress | P8: Manage IT governance framework
A9: Corporate IT body | B9: Manage IT governance framework | C9: Implementation LIS | D9: L1 | E9: MP | F9: 0 | J9: 46167 | K9: 46265 | L9: 71 | M9: NV | O9: Scheduled | P9: Manage IT governance framework
A10: Corporate IT body | B10: Manage IT governance framework | C10: Implementation COT | D10: L1 | E10: MP | F10: 0 | J10: ? | K10: ? | L10: 0 | M10: NV | P10: Manage IT governance framework
A11: Corporate IT body | B11: Manage IT governance framework | C11: Implementation LUS | D11: L1 | E11: MP | F11: 0 | J11: ? | K11: ? | L11: 0 | M11: NV | P11: Manage IT governance framework
A12: Corporate IT body | B12: Maintain IT glossary | C12: Total | D12: L2 | E12: MP | F12: 0.25 | J12: 46029 | K12: 46039 | L12: 8 | M12: NV | P12: Manage IT governance framework
A13: Corporate IT body | B13: Maintain IT glossary | C13: Elaboration | D13: L2 | E13: MP | F13: 0.25 | G13: Kunz Christina (LIS-MHP Management- und IT Beratung GmbH) | H13: Felder Max (LLI) | I13: Mielenz Thomas (LMT) | J13: 46029 | K13: ? | L13: 0 | M13: NV | P13: Manage IT governance framework
A14: Corporate IT body | B14: Maintain IT glossary | C14: Implementation LIS | D14: L2 | E14: MP | F14: 0 | J14: 46029 | K14: 46039 | L14: 7 | M14: NV | N14: Delayed | O14: Implementation LIS Done | P14: Manage IT governance framework
A15: Corporate IT body | B15: Maintain IT glossary | C15: Implementation COT | D15: L2 | E15: MP | F15: 0 | J15: 46029 | K15: ? | L15: 0 | M15: NV | P15: Manage IT governance framework
A16: Corporate IT body | B16: Maintain IT glossary | C16: Implementation LUS | D16: L2 | E16: MP | F16: 0 | J16: ? | K16: ? | L16: 0 | M16: NV | P16: Manage IT governance framework
A17: Corporate IT body | B17: Manage enterprise architecture | C17: Total | D17: L1 | E17: MP | F17: 0.24 | J17: 45946 | K17: 46219 | L17: 195.85 | M17: NV | P17: Manage enterprise architecture
A18: Corporate IT body | B18: Manage enterprise architecture | C18: Elaboration | D18: L1 | E18: MP | F18: 0 | G18: Hoermann Patrick (LLI) | H18: Gujral Parth (COB-COT-IT) | I18: Nussbaumer Florian (LBC) | J18: 46076 | K18: 46150 | L18: 54.85 | M18: NV | N18: Delayed | O18: Elaboration in progress | P18: Manage enterprise architecture
A19: Corporate IT body | B19: Manage enterprise architecture | C19: Implementation LIS | D19: L1 | E19: MP | F19: 0 | J19: 46150 | K19: 46219 | L19: 49 | M19: NV | O19: Scheduled | P19: Manage enterprise architecture
A20: Corporate IT body | B20: Manage enterprise architecture | C20: Implementation COT | D20: L1 | E20: MP | F20: 0 | J20: 46150 | K20: 46153 | L20: 1 | M20: NV | O20: Scheduled | P20: Manage enterprise architecture
A21: Corporate IT body | B21: Manage enterprise architecture | C21: Implementation LUS | D21: L1 | E21: MP | F21: 0 | J21: 46150 | K21: 46153 | L21: 1 | M21: NV | O21: Scheduled | P21: Manage enterprise architecture
A22: Corporate IT body | B22: Strategic architecture process | C22: Total | D22: L2 | E22: MP | F22: 0.5 | J22: 45946 | K22: 46142 | L22: 141 | M22: NV | P22: Manage enterprise architecture
A23: Corporate IT body | B23: Strategic architecture process | C23: Elaboration | D23: L2 | E23: MP | F23: 0.5 | G23: Hoermann Patrick (LLI) | H23: Gujral Parth (COB-COT-IT) | I23: Nussbaumer Florian (LBC) | J23: 46076 | K23: 46142 | L23: 49 | M23: NV | N23: Elaboration in progress | O23: Elaboration in progress | P23: Manage enterprise architecture
A24: Corporate IT body | B24: Strategic architecture process | C24: Implementation LIS | D24: L2 | E24: MP | F24: 0 | J24: ? | K24: ? | L24: 0 | M24: NV | P24: Manage enterprise architecture
A25: Corporate IT body | B25: Strategic architecture process | C25: Implementation COT | D25: L2 | E25: MP | F25: 0 | J25: ? | K25: ? | L25: 0 | M25: NV | P25: Manage enterprise architecture
A26: Corporate IT body | B26: Strategic architecture process | C26: Implementation LUS | D26: L2 | E26: MP | F26: 0 | J26: ? | K26: ? | L26: 0 | M26: NV | P26: Manage enterprise architecture
A27: ITSM | B27: Manage IT portfolio | C27: Total | D27: L1 | E27: MP | F27: 0.69 | J27: 45971 | K27: 46157 | L27: 135 | M27: NV | P27: Manage IT portfolio
A28: ITSM | B28: Manage IT portfolio | C28: Elaboration | D28: L1 | E28: MP | F28: 1 | G28: Frank Maren (LIS);Kunz Christina (LIS-MHP Management- und IT Beratung GmbH) | J28: 45972 | K28: 46051 | L28: 58 | M28: NV | N28: Elaboration Done | O28: Elaboration Done | P28: Manage IT portfolio
A29: ITSM | B29: Manage IT portfolio | C29: Implementation LIS | D29: L1 | E29: MP | F29: 0 | J29: ? | K29: ? | L29: 0 | M29: NV | P29: Manage IT portfolio
A30: ITSM | B30: Manage IT portfolio | C30: Implementation COT | D30: L1 | E30: MP | F30: 0 | J30: ? | K30: ? | L30: 0 | M30: NV | P30: Manage IT portfolio
A31: ITSM | B31: Manage IT portfolio | C31: Implementation LUS | D31: L1 | E31: MP | F31: 0 | J31: ? | K31: ? | L31: 0 | M31: NV | P31: Manage IT portfolio
A32: IT project management | B32: Manage IT project portfolio | C32: Total | D32: L2 | E32: MP | F32: 1 | J32: 45971 | K32: 46173 | L32: 145 | M32: NV | P32: Manage IT portfolio
A33: IT project management | B33: Manage IT project portfolio | C33: Elaboration | D33: L2 | E33: MP | F33: 1 | G33: Frank Maren (LIS) | H33: Mühlbacher Christian (LIS) | I33: Rollinger Alexander (LIS) | J33: 45971 | K33: 46001 | L33: 23 | M33: Mit 28.01.26 | N33: Elaboration Done | O33: Elaboration Done | P33: Manage IT portfolio
A34: IT project management | B34: Manage IT project portfolio | C34: Implementation LIS | D34: L2 | E34: MP | F34: 0 | J34: 46054 | K34: 46173 | L34: 85 | M34: NV | N34: Delayed | O34: Implementation LIS | P34: Manage IT portfolio
A35: IT project management | B35: Manage IT project portfolio | C35: Implementation COT | D35: L2 | E35: MP | F35: 0 | J35: ? | K35: ? | L35: 0 | M35: NV | P35: Manage IT portfolio
A36: IT project management | B36: Manage IT project portfolio | C36: Implementation LUS | D36: L2 | E36: MP | F36: 0 | J36: ? | K36: ? | L36: 0 | M36: NV | P36: Manage IT portfolio
A37: ITSM | B37: Manage IT service portfolio | C37: Total | D37: L2 | E37: MP | F37: 0 | J37: 46113 | K37: 46273 | L37: 115 | M37: NV | P37: Manage IT portfolio
A38: ITSM | B38: Manage IT service portfolio | C38: Elaboration | D38: L2 | E38: MP | F38: 0 | G38: Frank Maren (LIS);Kunz Christina (LIS-MHP Management- und IT Beratung GmbH) | H38: Ceilia Roser (LIS) | I38: Reiner Heiko (HAU-ITSA) | J38: 46113 | K38: 46155 | L38: 31 | M38: NV | O38: Scheduled | P38: Manage IT portfolio
A39: ITSM | B39: Manage IT service portfolio | C39: Implementation LIS | D39: L2 | E39: MP | F39: 0 | J39: 46188 | K39: 46273 | L39: 62 | M39: NV | O39: Scheduled | P39: Manage IT portfolio
A40: ITSM | B40: Manage IT service portfolio | C40: Implementation COT | D40: L2 | E40: MP | F40: 0 | J40: ? | K40: ? | L40: 0 | M40: NV | P40: Manage IT portfolio
...

Sheet Date_table_03_26
A1: Datum | B1: Elaboration | C1: Implementation LIS | D1: Implementation LUS | E1: Implementation COT
A2: 45870 | B2: {=SUMPRODUCT((Task_table_03_2_26!$C$2:$C$596=$B$1)*(A2>Task_table_03_2_26!$J$2:$J$596)*(A2<Task_table_03_2_26!$K$2:$K$596))} -> 0 | C2: {=SUMPRODUCT((Task_table_03_2_26!$C$2:$C$596=$C$1)*(A2>Task_table_03_2_26!$J$2:$J$596)*(A2<Task_table_03_2_26!$K$2:$K$596))} -> 1 | D2: {=SUMPRODUCT((Task_table_03_2_26!$C$2:$C$596=$D$1)*(A2>Task_table_03_2_26!$J$2:$J$596)*(A2<Task_table_03_2_26!$K$2:$K$596))} -> 0 | E2: {=SUMPRODUCT((Task_table_03_2_26!$C$2:$C$596=$E$1)*(A2>Task_table_03_2_26!$J$2:$J$596)*(A2<Task_table_03_2_26!$K$2:$K$596))} -> 0
A3: 45871 | B3: {=SUMPRODUCT((Task_table_03_2_26!$C$2:$C$596=$B$1)*(A3>Task_table_03_2_26!$J$2:$J$596)*(A3<Task_table_03_2_26!$K$2:$K$596))} -> 1 | C3: {=SUMPRODUCT((Task_table_03_2_26!$C$2:$C$596=$C$1)*(A3>Task_table_03_2_26!$J$2:$J$596)*(A3<Task_table_03_2_26!$K$2:$K$596))} -> 1 | D3: {=SUMPRODUCT((Task_table_03_2_26!$C$2:$C$596=$D$1)*(A3>Task_table_03_2_26!$J$2:$J$596)*(A3<Task_table_03_2_26!$K$2:$K$596))} -> 0 | E3: {=SUMPRODUCT((Task_table_03_2_26!$C$2:$C$596=$E$1)*(A3>Task_table_03_2_26!$J$2:$J$596)*(A3<Task_table_03_2_26!$K$2:$K$596))} -> 0
A4: 45872 | B4: {=SUMPRODUCT((Task_table_03_2_26!$C$2:$C$596=$B$1)*(A4>Task_table_03_2_26!$J$2:$J$596)*(A4<Task_table_03_2_26!$K$2:$K$596))} -> 1 | C4: {=SUMPRODUCT((Task_table_03_2_26!$C$2:$C$596=$C$1)*(A4>Task_table_03_2_26!$J$2:$J$596)*(A4<Task_table_03_2_26!$K$2:$K$596))} -> 1 | D4: {=SUMPRODUCT((Task_table_03_2_26!$C$2:$C$596=$D$1)*(A4>Task_table_03_2_26!$J$2:$J$596)*(A4<Task_table_03_2_26!$K$2:$K$596))} -> 0 | E4: {=SUMPRODUCT((Task_table_03_2_26!$C$2:$C$596=$E$1)*(A4>Task_table_03_2_26!$J$2:$J$596)*(A4<Task_table_03_2_26!$K$2:$K$596))} -> 0
A5: 45873 | B5: {=SUMPRODUCT((Task_table_03_2_26!$C$2:$C$596=$B$1)*(A5>Task_table_03_2_26!$J$2:$J$596)*(A5<Task_table_03_2_26!$K$2:$K$596))} -> 1 | C5: {=SUMPRODUCT((Task_table_03_2_26!$C$2:$C$596=$C$1)*(A5>Task_table_03_2_26!$J$2:$J$596)*(A5<Task_table_03_2_26!$K$2:$K$596))} -> 1 | D5: {=SUMPRODUCT((Task_table_03_2_26!$C$2:$C$596=$D$1)*(A5>Task_table_03_2_26!$J$2:$J$596)*(A5<Task_table_03_2_26!$K$2:$K$596))} -> 0 | E5: {=SUMPRODUCT((Task_table_03_2_26!$C$2:$C$596=$E$1)*(A5>Task_table_03_2_26!$J$2:$J$596)*(A5<Task_table_03_2_26!$K$2:$K$596))} -> 0
A6: 45874 | B6: {=SUMPRODUCT((Task_table_03_2_26!$C$2:$C$596=$B$1)*(A6>Task_table_03_2_26!$J$2:$J$596)*(A6<Task_table_03_2_26!$K$2:$K$596))} -> 2 | C6: {=SUMPRODUCT((Task_table_03_2_26!$C$2:$C$596=$C$1)*(A6>Task_table_03_2_26!$J$2:$J$596)*(A6<Task_table_03_2_26!$K$2:$K$596))} -> 1 | D6: {=SUMPRODUCT((Task_table_03_2_26!$C$2:$C$596=$D$1)*(A6>Task_table_03_2_26!$J$2:$J$596)*(A6<Task_table_03_2_26!$K$2:$K$596))} -> 0 | E6: {=SUMPRODUCT((Task_table_03_2_26!$C$2:$C$596=$E$1)*(A6>Task_table_03_2_26!$J$2:$J$596)*(A6<Task_table_03_2_26!$K$2:$K$596))} -> 0
A7: 45875 | B7: {=SUMPRODUCT((Task_table_03_2_26!$C$2:$C$596=$B$1)*(A7>Task_table_03_2_26!$J$2:$J$596)*(A7<Task_table_03_2_26!$K$2:$K$596))} -> 2 | C7: {=SUMPRODUCT((Task_table_03_2_26!$C$2:$C$596=$C$1)*(A7>Task_table_03_2_26!$J$2:$J$596)*(A7<Task_table_03_2_26!$K$2:$K$596))} -> 1 | D7: {=SUMPRODUCT((Task_table_03_2_26!$C$2:$C$596=$D$1)*(A7>Task_table_03_2_26!$J$2:$J$596)*(A7<Task_table_03_2_26!$K$2:$K$596))} -> 0 | E7: {=SUMPRODUCT((Task_table_03_2_26!$C$2:$C$596=$E$1)*(A7>Task_table_03_2_26!$J$2:$J$596)*(A7<Task_table_03_2_26!$K$2:$K$596))} -> 0
A8: 45876 | B8: {=SUMPRODUCT((Task_table_03_2_26!$C$2:$C$596=$B$1)*(A8>Task_table_03_2_26!$J$2:$J$596)*(A8<Task_table_03_2_26!$K$2:$K$596))} -> 2 | C8: {=SUMPRODUCT((Task_table_03_2_26!$C$2:$C$596=$C$1)*(A8>Task_table_03_2_26!$J$2:$J$596)*(A8<Task_table_03_2_26!$K$2:$K$596))} -> 1 | D8: {=SUMPRODUCT((Task_table_03_2_26!$C$2:$C$596=$D$1)*(A8>Task_table_03_2_26!$J$2:$J$596)*(A8<Task_table_03_2_26!$K$2:$K$596))} -> 0 | E8: {=SUMPRODUCT((Task_table_03_2_26!$C$2:$C$596=$E$1)*(A8>Task_table_03_2_26!$J$2:$J$596)*(A8<Task_table_03_2_26!$K$2:$K$596))} -> 0
A9: 45877 | B9: {=SUMPRODUCT((Task_table_03_2_26!$C$2:$C$596=$B$1)*(A9>Task_table_03_2_26!$J$2:$J$596)*(A9<Task_table_03_2_26!$K$2:$K$596))} -> 2 | C9: {=SUMPRODUCT((Task_table_03_2_26!$C$2:$C$596=$C$1)*(A9>Task_table_03_2_26!$J$2:$J$596)*(A9<Task_table_03_2_26!$K$2:$K$596))} -> 1 | D9: {=SUMPRODUCT((Task_table_03_2_26!$C$2:$C$596=$D$1)*(A9>Task_table_03_2_26!$J$2:$J$596)*(A9<Task_table_03_2_26!$K$2:$K$596))} -> 0 | E9: {=SUMPRODUCT((Task_table_03_2_26!$C$2:$C$596=$E$1)*(A9>Task_table_03_2_26!$J$2:$J$596)*(A9<Task_table_03_2_26!$K$2:$K$596))} -> 0
A10: 45878 | B10: {=SUMPRODUCT((Task_table_03_2_26!$C$2:$C$596=$B$1)*(A10>Task_table_03_2_26!$J$2:$J$596)*(A10<Task_table_03_2_26!$K$2:$K$596))} -> 2 | C10: {=SUMPRODUCT((Task_table_03_2_26!$C$2:$C$596=$C$1)*(A10>Task_table_03_2_26!$J$2:$J$596)*(A10<Task_table_03_2_26!$K$2:$K$596))} -> 1 | D10: {=SUMPRODUCT((Task_table_03_2_26!$C$2:$C$596=$D$1)*(A10>Task_table_03_2_26!$J$2:$J$596)*(A10<Task_table_03_2_26!$K$2:$K$596))} -> 0 | E10: {=SUMPRODUCT((Task_table_03_2_26!$C$2:$C$596=$E$1)*(A10>Task_table_03_2_26!$J$2:$J$596)*(A10<Task_table_03_2_26!$K$2:$K$596))} -> 0
A11: 45879 | B11: {=SUMPRODUCT((Task_table_03_2_26!$C$2:$C$596=$B$1)*(A11>Task_table_03_2_26!$J$2:$J$596)*(A11<Task_table_03_2_26!$K$2:$K$596))} -> 2 | C11: {=SUMPRODUCT((Task_table_03_2_26!$C$2:$C$596=$C$1)*(A11>Task_table_03_2_26!$J$2:$J$596)*(A11<Task_table_03_2_26!$K$2:$K$596))} -> 1 | D11: {=SUMPRODUCT((Task_table_03_2_26!$C$2:$C$596=$D$1)*(A11>Task_table_03_2_26!$J$2:$J$596)*(A11<Task_table_03_2_26!$K$2:$K$596))} -> 0 | E11: {=SUMPRODUCT((Task_table_03_2_26!$C$2:$C$596=$E$1)*(A11>Task_table_03_2_26!$J$2:$J$596)*(A11<Task_table_03_2_26!$K$2:$K$596))} -> 0
A12: 45880 | B12: {=SUMPRODUCT((Task_table_03_2_26!$C$2:$C$596=$B$1)*(A12>Task_table_03_2_26!$J$2:$J$596)*(A12<Task_table_03_2_26!$K$2:$K$596))} -> 2 | C12: {=SUMPRODUCT((Task_table_03_2_26!$C$2:$C$596=$C$1)*(A12>Task_table_03_2_26!$J$2:$J$596)*(A12<Task_table_03_2_26!$K$2:$K$596))} -> 1 | D12: {=SUMPRODUCT((Task_table_03_2_26!$C$2:$C$596=$D$1)*(A12>Task_table_03_2_26!$J$2:$J$596)*(A12<Task_table_03_2_26!$K$2:$K$596))} -> 0 | E12: {=SUMPRODUCT((Task_table_03_2_26!$C$2:$C$596=$E$1)*(A12>Task_table_03_2_26!$J$2:$J$596)*(A12<Task_table_03_2_26!$K$2:$K$596))} -> 0
A13: 45881 | B13: {=SUMPRODUCT((Task_table_03_2_26!$C$2:$C$596=$B$1)*(A13>Task_table_03_2_26!$J$2:$J$596)*(A13<Task_table_03_2_26!$K$2:$K$596))} -> 2 | C13: {=SUMPRODUCT((Task_table_03_2_26!$C$2:$C$596=$C$1)*(A13>Task_table_03_2_26!$J$2:$J$596)*(A13<Task_table_03_2_26!$K$2:$K$596))} -> 1 | D13: {=SUMPRODUCT((Task_table_03_2_26!$C$2:$C$596=$D$1)*(A13>Task_table_03_2_26!$J$2:$J$596)*(A13<Task_table_03_2_26!$K$2:$K$596))} -> 0 | E13: {=SUMPRODUCT((Task_table_03_2_26!$C$2:$C$596=$E$1)*(A13>Task_table_03_2_26!$J$2:$J$596)*(A13<Task_table_03_2_26!$K$2:$K$596))} -> 0
... A520: 46388 | B520: {=SUMPRODUCT((Task_table_03_2_26!$C$2:$C$596=$B$1)*(A520>Task_table_03_2_26!$J$2:$J$596)*(A520<Task_table_03_2_26!$K$2:$K$596))} -> 22 | C520: {=SUMPRODUCT((Task_table_03_2_26!$C$2:$C$596=$C$1)*(A520>Task_table_03_2_26!$J$2:$J$596)*(A520<Task_table_03_2_26!$K$2:$K$596))} -> 0 | D520: {=SUMPRODUCT((Task_table_03_2_26!$C$2:$C$596=$D$1)*(A520>Task_table_03_2_26!$J$2:$J$596)*(A520<Task_table_03_2_26!$K$2:$K$596))} -> 0 | E520: {=SUMPRODUCT((Task_table_03_2_26!$C$2:$C$596=$E$1)*(A520>Task_table_03_2_26!$J$2:$J$596)*(A520<Task_table_03_2_26!$K$2:$K$596))} -> 1

Sheet Task_table_03_2_26
A1: Initiative | B1: Process | C1: Phase | D1: Process level | E1: Process Group | F1: % Arbeit abgeschlossen | G1: IT Process Consultant | H1: IT Process Initiative Lead | I1: IT Process Manager | J1: Anfang | K1: Ende | L1: Dauer2 | M1: Process Approval Date | N1: Actual Phase | O1: Planned phase | P1: Associated Process on L1 | R1: 📌 Analyse
A2: Corporate IT body | B2: Manage IT strategy | C2: Total | D2: L1 | E2: MP | F2: 0.5 | J2: 46055 | K2: 46232 | L2: 128 | M2: Mit 06.05.26 | O2: 1 | P2: Manage IT strategy | R2: Prozesse in Elaboration | S2: 39
A3: Corporate IT body | B3: Manage IT strategy | C3: Elaboration | D3: L1 | E3: MP | F3: 0.5 | G3: Kreis Andreas (LLI) | H3: Felder Max (LLI) | I3: Mielenz Thomas (LMT) | J3: 46055 | K3: 46142 | L3: 64 | M3: NV | N3: Elaboration in progress | O3: Elaboration in progress | P3: Manage IT strategy
A4: Corporate IT body | B4: Manage IT strategy | C4: Implementation LIS | D4: L1 | E4: MP | F4: 0 | J4: 46156 | K4: 46232 | L4: 55 | M4: NV | O4: Scheduled | P4: Manage IT strategy
A5: Corporate IT body | B5: Manage IT strategy | C5: Implementation COT | D5: L1 | E5: MP | F5: 0 | J5: ? | K5: ? | L5: 0 | M5: NV | P5: Manage IT strategy
A6: Corporate IT body | B6: Manage IT strategy | C6: Implementation LUS | D6: L1 | E6: MP | F6: 0 | J6: ? | K6: ? | L6: 0 | M6: NV | P6: Manage IT strategy
A7: Corporate IT body | B7: Manage IT governance framework | C7: Total | D7: L1 | E7: MP | F7: 0.5 | J7: 46029 | K7: 46265 | L7: 169 | M7: NV | P7: Manage IT governance framework
A8: Corporate IT body | B8: Manage IT governance framework | C8: Elaboration | D8: L1 | E8: MP | F8: 0.5 | G8: Kunz Christina (LIS-MHP Management- und IT Beratung GmbH);Kreis Andreas (LLI) | H8: Felder Max (LLI) | I8: Mielenz Thomas (LMT) | J8: 46097 | K8: 46163 | L8: 49 | M8: NV | N8: Elaboration in progress | O8: Elaboration in progress | P8: Manage IT governance framework
A9: Corporate IT body | B9: Manage IT governance framework | C9: Implementation LIS | D9: L1 | E9: MP | F9: 0 | J9: 46167 | K9: 46265 | L9: 71 | M9: NV | O9: Scheduled | P9: Manage IT governance framework
A10: Corporate IT body | B10: Manage IT governance framework | C10: Implementation COT | D10: L1 | E10: MP | F10: 0 | J10: ? | K10: ? | L10: 0 | M10: NV | P10: Manage IT governance framework
A11: Corporate IT body | B11: Manage IT governance framework | C11: Implementation LUS | D11: L1 | E11: MP | F11: 0 | J11: ? | K11: ? | L11: 0 | M11: NV | P11: Manage IT governance framework
A12: Corporate IT body | B12: Maintain IT glossary | C12: Total | D12: L2 | E12: MP | F12: 0.25 | J12: 46029 | K12: 46039 | L12: 8 | M12: NV | P12: Manage IT governance framework
A13: Corporate IT body | B13: Maintain IT glossary | C13: Elaboration | D13: L2 | E13: MP | F13: 0.25 | G13: Kunz Christina (LIS-MHP Management- und IT Beratung GmbH) | H13: Felder Max (LLI) | I13: Mielenz Thomas (LMT) | J13: 46029 | K13: ? | L13: 0 | M13: NV | P13: Manage IT governance framework
A14: Corporate IT body | B14: Maintain IT glossary | C14: Implementation LIS | D14: L2 | E14: MP | F14: 0 | J14: 46029 | K14: 46039 | L14: 7 | M14: NV | N14: Delayed | O14: Implementation LIS Done | P14: Manage IT governance framework
A15: Corporate IT body | B15: Maintain IT glossary | C15: Implementation COT | D15: L2 | E15: MP | F15: 0 | J15: 46029 | K15: ? | L15: 0 | M15: NV | P15: Manage IT governance framework
A16: Corporate IT body | B16: Maintain IT glossary | C16: Implementation LUS | D16: L2 | E16: MP | F16: 0 | J16: ? | K16: ? | L16: 0 | M16: NV | P16: Manage IT governance framework
A17: Corporate IT body | B17: Manage enterprise architecture | C17: Total | D17: L1 | E17: MP | F17: 0.24 | J17: 45946 | K17: 46219 | L17: 195.85 | M17: NV | P17: Manage enterprise architecture
A18: Corporate IT body | B18: Manage enterprise architecture | C18: Elaboration | D18: L1 | E18: MP | F18: 0 | G18: Hoermann Patrick (LLI) | H18: Gujral Parth (COB-COT-IT) | I18: Nussbaumer Florian (LBC) | J18: 46076 | K18: 46150 | L18: 54.85 | M18: NV | N18: Delayed | O18: Elaboration in progress | P18: Manage enterprise architecture
A19: Corporate IT body | B19: Manage enterprise architecture | C19: Implementation LIS | D19: L1 | E19: MP | F19: 0 | J19: 46150 | K19: 46219 | L19: 49 | M19: NV | O19: Scheduled | P19: Manage enterprise architecture
A20: Corporate IT body | B20: Manage enterprise architecture | C20: Implementation COT | D20: L1 | E20: MP | F20: 0 | J20: 46150 | K20: 46153 | L20: 1 | M20: NV | O20: Scheduled | P20: Manage enterprise architecture
A21: Corporate IT body | B21: Manage enterprise architecture | C21: Implementation LUS | D21: L1 | E21: MP | F21: 0 | J21: 46150 | K21: 46153 | L21: 1 | M21: NV | O21: Scheduled | P21: Manage enterprise architecture
A22: Corporate IT body | B22: Strategic architecture process | C22: Total | D22: L2 | E22: MP | F22: 0.5 | J22: 45946 | K22: 46142 | L22: 141 | M22: NV | P22: Manage enterprise architecture
A23: Corporate IT body | B23: Strategic architecture process | C23: Elaboration | D23: L2 | E23: MP | F23: 0.5 | G23: Hoermann Patrick (LLI) | H23: Gujral Parth (COB-COT-IT) | I23: Nussbaumer Florian (LBC) | J23: 46076 | K23: 46142 | L23: 49 | M23: NV | N23: Elaboration in progress | O23: Elaboration in progress | P23: Manage enterprise architecture
A24: Corporate IT body | B24: Strategic architecture process | C24: Implementation LIS | D24: L2 | E24: MP | F24: 0 | J24: ? | K24: ? | L24: 0 | M24: NV | P24: Manage enterprise architecture
A25: Corporate IT body | B25: Strategic architecture process | C25: Implementation COT | D25: L2 | E25: MP | F25: 0 | J25: ? | K25: ? | L25: 0 | M25: NV | P25: Manage enterprise architecture
A26: Corporate IT body | B26: Strategic architecture process | C26: Implementation LUS | D26: L2 | E26: MP | F26: 0 | J26: ? | K26: ? | L26: 0 | M26: NV | P26: Manage enterprise architecture
A27: ITSM | B27: Manage IT portfolio | C27: Total | D27: L1 | E27: MP | F27: 0.69 | J27: 45971 | K27: 46157 | L27: 135 | M27: NV | P27: Manage IT portfolio
A28: ITSM | B28: Manage IT portfolio | C28: Elaboration | D28: L1 | E28: MP | F28: 1 | G28: Frank Maren (LIS);Kunz Christina (LIS-MHP Management- und IT Beratung GmbH) | J28: 45972 | K28: 46051 | L28: 58 | M28: NV | N28: Elaboration Done | O28: Elaboration Done | P28: Manage IT portfolio
A29: ITSM | B29: Manage IT portfolio | C29: Implementation LIS | D29: L1 | E29: MP | F29: 0 | J29: ? | K29: ? | L29: 0 | M29: NV | P29: Manage IT portfolio
A30: ITSM | B30: Manage IT portfolio | C30: Implementation COT | D30: L1 | E30: MP | F30: 0 | J30: ? | K30: ? | L30: 0 | M30: NV | P30: Manage IT portfolio
A31: ITSM | B31: Manage IT portfolio | C31: Implementation LUS | D31: L1 | E31: MP | F31: 0 | J31: ? | K31: ? | L31: 0 | M31: NV | P31: Manage IT portfolio
A32: IT project management | B32: Manage IT project portfolio | C32: Total | D32: L2 | E32: MP | F32: 1 | J32: 45971 | K32: 46173 | L32: 145 | M32: NV | P32: Manage IT portfolio
A33: IT project management | B33: Manage IT project portfolio | C33: Elaboration | D33: L2 | E33: MP | F33: 1 | G33: Frank Maren (LIS) | H33: Mühlbacher Christian (LIS) | I33: Rollinger Alexander (LIS) | J33: 45971 | K33: 46001 | L33: 23 | M33: Mit 28.01.26 | N33: Elaboration Done | O33: Elaboration Done | P33: Manage IT portfolio
A34: IT project management | B34: Manage IT project portfolio | C34: Implementation LIS | D34: L2 | E34: MP | F34: 0 | J34: 46054 | K34: 46173 | L34: 85 | M34: NV | N34: Delayed | O34: Implementation LIS | P34: Manage IT portfolio
A35: IT project management | B35: Manage IT project portfolio | C35: Implementation COT | D35: L2 | E35: MP | F35: 0 | J35: ? | K35: ? | L35: 0 | M35: NV | P35: Manage IT portfolio
A36: IT project management | B36: Manage IT project portfolio | C36: Implementation LUS | D36: L2 | E36: MP | F36: 0 | J36: ? | K36: ? | L36: 0 | M36: NV | P36: Manage IT portfolio
A37: ITSM | B37: Manage IT service portfolio | C37: Total | D37: L2 | E37: MP | F37: 0 | J37: 46113 | K37: 46273 | L37: 115 | M37: NV | P37: Manage IT portfolio
A38: ITSM | B38: Manage IT service portfolio | C38: Elaboration | D38: L2 | E38: MP | F38: 0 | G38: Frank Maren (LIS);Kunz Christina (LIS-MHP Management- und IT Beratung GmbH) | H38: Ceilia Roser (LIS) | I38: Reiner Heiko (HAU-ITSA) | J38: 46113 | K38: 46155 | L38: 31 | M38: NV | O38: Scheduled | P38: Manage IT portfolio
A39: ITSM | B39: Manage IT service portfolio | C39: Implementation LIS | D39: L2 | E39: MP | F39: 0 | J39: 46188 | K39: 46273 | L39: 62 | M39: NV | O39: Scheduled | P39: Manage IT portfolio
A40: ITSM | B40: Manage IT service portfolio | C40: Implementation COT | D40: L2 | E40: MP | F40: 0 | J40: ? | K40: ? | L40: 0 | M40: NV | P40: Manage IT portfolio
...

Sheet Date_table_03_2_26
A1: Datum | B1: Elaboration | C1: Implementation LIS | D1: Implementation LUS | E1: Implementation COT
A2: 45870 | B2: {=SUMPRODUCT((Task_table_03_2_26!$C$2:$C$596=$B$1)*(A2>Task_table_03_2_26!$J$2:$J$596)*(A2<Task_table_03_2_26!$K$2:$K$596))} -> 0 | C2: {=SUMPRODUCT((Task_table_03_2_26!$C$2:$C$596=$C$1)*(A2>Task_table_03_2_26!$J$2:$J$596)*(A2<Task_table_03_2_26!$K$2:$K$596))} -> 1 | D2: {=SUMPRODUCT((Task_table_03_2_26!$C$2:$C$596=$D$1)*(A2>Task_table_03_2_26!$J$2:$J$596)*(A2<Task_table_03_2_26!$K$2:$K$596))} -> 0 | E2: {=SUMPRODUCT((Task_table_03_2_26!$C$2:$C$596=$E$1)*(A2>Task_table_03_2_26!$J$2:$J$596)*(A2<Task_table_03_2_26!$K$2:$K$596))} -> 0
A3: 45871 | B3: {=SUMPRODUCT((Task_table_03_2_26!$C$2:$C$596=$B$1)*(A3>Task_table_03_2_26!$J$2:$J$596)*(A3<Task_table_03_2_26!$K$2:$K$596))} -> 1 | C3: {=SUMPRODUCT((Task_table_03_2_26!$C$2:$C$596=$C$1)*(A3>Task_table_03_2_26!$J$2:$J$596)*(A3<Task_table_03_2_26!$K$2:$K$596))} -> 1 | D3: {=SUMPRODUCT((Task_table_03_2_26!$C$2:$C$596=$D$1)*(A3>Task_table_03_2_26!$J$2:$J$596)*(A3<Task_table_03_2_26!$K$2:$K$596))} -> 0 | E3: {=SUMPRODUCT((Task_table_03_2_26!$C$2:$C$596=$E$1)*(A3>Task_table_03_2_26!$J$2:$J$596)*(A3<Task_table_03_2_26!$K$2:$K$596))} -> 0
A4: 45872 | B4: {=SUMPRODUCT((Task_table_03_2_26!$C$2:$C$596=$B$1)*(A4>Task_table_03_2_26!$J$2:$J$596)*(A4<Task_table_03_2_26!$K$2:$K$596))} -> 1 | C4: {=SUMPRODUCT((Task_table_03_2_26!$C$2:$C$596=$C$1)*(A4>Task_table_03_2_26!$J$2:$J$596)*(A4<Task_table_03_2_26!$K$2:$K$596))} -> 1 | D4: {=SUMPRODUCT((Task_table_03_2_26!$C$2:$C$596=$D$1)*(A4>Task_table_03_2_26!$J$2:$J$596)*(A4<Task_table_03_2_26!$K$2:$K$596))} -> 0 | E4: {=SUMPRODUCT((Task_table_03_2_26!$C$2:$C$596=$E$1)*(A4>Task_table_03_2_26!$J$2:$J$596)*(A4<Task_table_03_2_26!$K$2:$K$596))} -> 0
A5: 45873 | B5: {=SUMPRODUCT((Task_table_03_2_26!$C$2:$C$596=$B$1)*(A5>Task_table_03_2_26!$J$2:$J$596)*(A5<Task_table_03_2_26!$K$2:$K$596))} -> 1 | C5: {=SUMPRODUCT((Task_table_03_2_26!$C$2:$C$596=$C$1)*(A5>Task_table_03_2_26!$J$2:$J$596)*(A5<Task_table_03_2_26!$K$2:$K$596))} -> 1 | D5: {=SUMPRODUCT((Task_table_03_2_26!$C$2:$C$596=$D$1)*(A5>Task_table_03_2_26!$J$2:$J$596)*(A5<Task_table_03_2_26!$K$2:$K$596))} -> 0 | E5: {=SUMPRODUCT((Task_table_03_2_26!$C$2:$C$596=$E$1)*(A5>Task_table_03_2_26!$J$2:$J$596)*(A5<Task_table_03_2_26!$K$2:$K$596))} -> 0
A6: 45874 | B6: {=SUMPRODUCT((Task_table_03_2_26!$C$2:$C$596=$B$1)*(A6>Task_table_03_2_26!$J$2:$J$596)*(A6<Task_table_03_2_26!$K$2:$K$596))} -> 2 | C6: {=SUMPRODUCT((Task_table_03_2_26!$C$2:$C$596=$C$1)*(A6>Task_table_03_2_26!$J$2:$J$596)*(A6<Task_table_03_2_26!$K$2:$K$596))} -> 1 | D6: {=SUMPRODUCT((Task_table_03_2_26!$C$2:$C$596=$D$1)*(A6>Task_table_03_2_26!$J$2:$J$596)*(A6<Task_table_03_2_26!$K$2:$K$596))} -> 0 | E6: {=SUMPRODUCT((Task_table_03_2_26!$C$2:$C$596=$E$1)*(A6>Task_table_03_2_26!$J$2:$J$596)*(A6<Task_table_03_2_26!$K$2:$K$596))} -> 0
A7: 45875 | B7: {=SUMPRODUCT((Task_table_03_2_26!$C$2:$C$596=$B$1)*(A7>Task_table_03_2_26!$J$2:$J$596)*(A7<Task_table_03_2_26!$K$2:$K$596))} -> 2 | C7: {=SUMPRODUCT((Task_table_03_2_26!$C$2:$C$596=$C$1)*(A7>Task_table_03_2_26!$J$2:$J$596)*(A7<Task_table_03_2_26!$K$2:$K$596))} -> 1 | D7: {=SUMPRODUCT((Task_table_03_2_26!$C$2:$C$596=$D$1)*(A7>Task_table_03_2_26!$J$2:$J$596)*(A7<Task_table_03_2_26!$K$2:$K$596))} -> 0 | E7: {=SUMPRODUCT((Task_table_03_2_26!$C$2:$C$596=$E$1)*(A7>Task_table_03_2_26!$J$2:$J$596)*(A7<Task_table_03_2_26!$K$2:$K$596))} -> 0
